Workbook

Sheet SUMMARY
C4: Results | D4: MVA | E4: BEL | F4: BoF | G4: d_BoF | H4: dur_L | L4: =BSCR!U4 -> SCR | O4: SCR_market | P4: =BSCR!E18 -> 2221.1875
C5: BASE | D5: =BASE!D2 -> 100000 | E5: =BASE!Q56 -> 94493.616 | F5: =BASE!Q57 -> 5506.3842 | G5: =$F$5-F5 -> 0 | H5: =BASE!Q59 -> 5.6130734 | L5: =BSCR!U5 -> Equity | M5: =BSCR!V5 -> 1790.2664 | O5: SCR_life | P5: =BSCR!E20 -> 1568.0585
C6: EQ STRESS 1 | D6: ='EQ STRESS 1'!D2 -> 68800 | E6: ='EQ STRESS 1'!Q56 -> 65083.882 | F6: ='EQ STRESS 1'!Q57 -> 3716.1178 | G6: =$F$5-F6 -> 1790.2664 | H6: ='EQ STRESS 1'!Q59 -> 5.6132956 | L6: =BSCR!U6 -> Property | M6: =BSCR!V6 -> 286.90166
C7: PROP STRESS | D7: ='PROPERTY STRESS'!$D$2 -> 95000 | E7: ='PROPERTY STRESS'!$Q$56 -> 89780.518 | F7: ='PROPERTY STRESS'!$Q$57 -> 5219.4825 | G7: =$F$5-$F$7 -> 286.90166 | H7: ='PROPERTY STRESS'!$Q$59 -> 5.6130992 | L7: =BSCR!U7 -> IR up | M7: =BSCR!V7 -> 0 | O7: BSCR | P7: =BSCR!K17 -> 3022.2438
C8: IR UP | D8: ='IR UP '!$D$2 -> 100000 | E8: ='IR UP '!$Q$56 -> 94477.93 | F8: ='IR UP '!$Q$57 -> 5522.0696 | G8: =$F$5-$F$8 -> -15.685468 | H8: ='IR UP '!$Q$59 -> 5.6125887 | L8: =BSCR!U8 -> IR down | M8: =BSCR!V8 -> 359.457
C9: IR DOWN | D9: ='IR DOWN '!$D$2 -> 100000 | E9: ='IR DOWN '!$Q$56 -> 94853.073 | F9: ='IR DOWN '!$Q$57 -> 5146.9271 | G9: =$F$5-$F$9 -> 359.457 | H9: ='IR DOWN '!$Q$59 -> 5.6400305 | L9: =BSCR!U9 -> Expense | M9: =BSCR!V9 -> 38.106405
C10: EXPENSE STRESS | D10: ='EXPENSE STRESS'!$D$2 -> 100000 | E10: ='EXPENSE STRESS'!$Q$56 -> 94531.722 | F10: ='EXPENSE STRESS'!$Q$57 -> 5468.2777 | G10: =$F$5-$F$10 -> 38.106405 | H10: ='EXPENSE STRESS'!$Q$59 -> 5.6138741 | L10: =BSCR!U10 -> Mortality | M10: =BSCR!V10 -> 29.30665 | O10: BASE CASE | P10: =BASE!P61 -> PVFP | Q10: =BASE!Q61 -> 3765.8683
C11: MORTALITY | D11: ='LIFE CAT'!$D$2 -> 100000 | E11: ='LIFE CAT'!$Q$56 -> 94498.608 | F11: ='LIFE CAT'!$Q$57 -> 5501.3923 | G11: =$F$5-$F$11 -> 4.991863 | H11: ='LIFE CAT'!$Q$59 -> 5.6058654 | L11: =BSCR!U11 -> Cat | M11: =BSCR!V11 -> 4.991863 | P11: =BASE!P62 -> LEAK | Q11: =BASE!Q62 -> 1740.5158
C12: LIFE CAT | D12: ='LIFE CAT'!$D$2 -> 100000 | E12: ='LIFE CAT'!$Q$56 -> 94498.608 | F12: ='LIFE CAT'!$Q$57 -> 5501.3923 | G12: =$F$5-$F$12 -> 4.991863 | H12: ='LIFE CAT'!$Q$59 -> 5.6058654 | L12: =BSCR!U12 -> Lapse up | M12: =BSCR!V12 -> 1130.4727 | P12: =BASE!P63 -> PVFP PROXY | Q12: =BASE!Q63 -> 4490.4587
C13: LAPSE UP | D13: ='LAPSE STRESS UP '!$D$2 -> 100000 | E13: ='LAPSE STRESS UP '!$Q$56 -> 95624.089 | F13: ='LAPSE STRESS UP '!$Q$57 -> 4375.9114 | G13: =$F$5-$F$13 -> 1130.4727 | H13: ='LAPSE STRESS UP '!$Q$59 -> 4.0158341 | L13: =BSCR!U13 -> Lapse down | M13: =BSCR!V13 -> 0
C14: LASPE DOWN | D14: ='LAPSE STRESS DOWN'!$D$2 -> 100000 | E14: ='LAPSE STRESS DOWN'!$Q$56 -> 92119.809 | F14: ='LAPSE STRESS DOWN'!$Q$57 -> 7880.1908 | G14: =$F$5-$F$14 -> -2373.8067 | H14: ='LAPSE STRESS DOWN'!$Q$59 -> 9.0321241 | L14: =BSCR!U14 -> Lapse mass | M14: =BSCR!V14 -> 1546.912
C15: LASPE MASS | D15: ='LAPSE MASS'!$D$2 -> 100000 | E15: ='LAPSE MASS'!$Q$56 -> 96040.528 | F15: ='LAPSE MASS'!$Q$57 -> 3959.4721 | G15: =$F$5-$F$15 -> 1546.912 | H15: ='LAPSE MASS'!$Q$59 -> 3.4028789

Sheet RATES
C1: RFR_SPPT_NO_VA | D1: SPOT_NO_VA_SHOCK_UP | E1: SPOT_NO_VA_SHOCK_DOWN | G1: DISCOUNTS | K1: FWD DISCOUNTS | O1: FWD RATES
C2: Euro | D2: Euro | E2: Euro | G2: BASE | H2: UP | I2: DOWN | K2: BASE | L2: UP | M2: DOWN | O2: BASE | P2: UP | Q2: DOWN
C3: EUR_31_03_2024_SWP_LLP_20_EXT_40_UFR_3.30 | D3: EUR_31_03_2024_SWP_LLP_20_EXT_40_UFR_3.30 | E3: EUR_31_03_2024_SWP_LLP_20_EXT_40_UFR_3.30 | G3: 1 | H3: 1 | I3: 1
B4: 1 | C4: 0.03514 | D4: 0.05974 | E4: 0.00879 | G4: =(1+C4)^(-$B4) -> 0.9660529 | H4: =(1+D4)^(-$B4) -> 0.94362768 | I4: =(1+E4)^(-$B4) -> 0.99128659 | K4: =G4/G3 -> 0.9660529 | L4: =H4/H3 -> 0.94362768 | M4: =I4/I3 -> 0.99128659 | O4: =-LN(K4) -> 0.034536683 | P4: =-LN(L4) -> 0.058023595 | Q4: =-LN(M4) -> 0.0087515929
B5: 2 | C5: 0.03035 | D5: 0.0516 | E5: 0.01062 | G5: =(1+C5)^(-$B5) -> 0.94195564 | H5: =(1+D5)^(-$B5) -> 0.9042715 | I5: =(1+E5)^(-$B5) -> 0.97909362 | K5: =G5/G4 -> 0.97505596 | L5: =H5/H4 -> 0.95829268 | M5: =I5/I4 -> 0.98769986 | O5: =-LN(K5) -> 0.025260417 | P5: =-LN(L5) -> 0.042602033 | Q5: =-LN(M5) -> 0.012376415
B6: 3 | C6: 0.02783 | D6: 0.04564 | E6: 0.01225 | G6: =(1+C6)^(-$B6) -> 0.92095017 | H6: =(1+D6)^(-$B6) -> 0.87468854 | I6: =(1+E6)^(-$B6) -> 0.96413232 | K6: =G6/G5 -> 0.97770015 | L6: =H6/H5 -> 0.9672853 | M6: =I6/I5 -> 0.98471923 | O6: =-LN(K6) -> 0.02255225 | P6: =-LN(L6) -> 0.033261787 | Q6: =-LN(M6) -> 0.01539872
B7: 4 | C7: 0.02637 | D7: 0.04193 | E7: 0.01319 | G7: =(1+C7)^(-$B7) -> 0.90112326 | H7: =(1+D7)^(-$B7) -> 0.84848824 | I7: =(1+E7)^(-$B7) -> 0.9489349 | K7: =G7/G6 -> 0.97847125 | L7: =H7/H6 -> 0.97004615 | M7: =I7/I6 -> 0.9842372 | O7: =-LN(K7) -> 0.021763871 | P7: =-LN(L7) -> 0.030411636 | Q7: =-LN(M7) -> 0.01588835
B8: 5 | C8: 0.02549 | D8: 0.03951 | E8: 0.01376 | G8: =(1+C8)^(-$B8) -> 0.88174469 | H8: =(1+D8)^(-$B8) -> 0.82386612 | I8: =(1+E8)^(-$B8) -> 0.93395133 | K8: =G8/G7 -> 0.97849509 | L8: =H8/H7 -> 0.97098118 | M8: =I8/I7 -> 0.98421011 | O8: =-LN(K8) -> 0.021739514 | P8: =-LN(L8) -> 0.029448191 | Q8: =-LN(M8) -> 0.015915876
B9: 6 | C9: 0.02502 | D9: 0.03803 | E9: 0.01451 | G9: =(1+C9)^(-$B9) -> 0.86219592 | H9: =(1+D9)^(-$B9) -> 0.79935661 | I9: =(1+E9)^(-$B9) -> 0.91719569 | K9: =G9/G8 -> 0.97782945 | L9: =H9/H8 -> 0.97025061 | M9: =I9/I8 -> 0.98205941 | O9: =-LN(K9) -> 0.022420012 | P9: =-LN(L9) -> 0.030200875 | Q9: =-LN(M9) -> 0.01810347
B10: 7 | C10: 0.02477 | D10: 0.03691 | E10: 0.01511 | G10: =(1+C10)^(-$B10) -> 0.84258782 | H10: =(1+D10)^(-$B10) -> 0.77591216 | I10: =(1+E10)^(-$B10) -> 0.90034355 | K10: =G10/G9 -> 0.97725796 | L10: =H10/H9 -> 0.97067086 | M10: =I10/I9 -> 0.98162645 | O10: =-LN(K10) -> 0.023004633 | P10: =-LN(L10) -> 0.02976784 | Q10: =-LN(M10) -> 0.018544443
B11: 8 | C11: 0.02466 | D11: 0.03625 | E11: 0.01578 | G11: =(1+C11)^(-$B11) -> 0.82292781 | H11: =(1+D11)^(-$B11) -> 0.75211396 | I11: =(1+E11)^(-$B11) -> 0.88227249 | K11: =G11/G10 -> 0.9766671 | L11: =H11/H10 -> 0.96932874 | M11: =I11/I10 -> 0.97992871 | O11: =-LN(K11) -> 0.023609422 | P11: =-LN(L11) -> 0.031151463 | Q11: =-LN(M11) -> 0.020275455
B12: 9 | C12: 0.02464 | D12: 0.03548 | E12: 0.01651 | G12: =(1+C12)^(-$B12) -> 0.8032639 | H12: =(1+D12)^(-$B12) -> 0.73067553 | I12: =(1+E12)^(-$B12) -> 0.86296881 | K12: =G12/G11 -> 0.97610494 | L12: =H12/H11 -> 0.97149577 | M12: =I12/I11 -> 0.9781205 | O12: =-LN(K12) -> 0.024185181 | P12: =-LN(L12) -> 0.028918366 | Q12: =-LN(M12) -> 0.022122403
B13: 10 | C13: 0.0247 | D13: 0.03507 | E13: 0.01704 | G13: =(1+C13)^(-$B13) -> 0.78348852 | H13: =(1+D13)^(-$B13) -> 0.70843953 | I13: =(1+E13)^(-$B13) -> 0.8445389 | K13: =G13/G12 -> 0.97538122 | L13: =H13/H12 -> 0.96956788 | M13: =I13/I12 -> 0.9786436 | O13: =-LN(K13) -> 0.024926886 | P13: =-LN(L13) -> 0.030904787 | Q13: =-LN(M13) -> 0.021587751
B14: 11 | C14: 0.02487 | D14: 0.03487 | E14: 0.01741 | G14: =(1+C14)^(-$B14) -> 0.76320888 | H14: =(1+D14)^(-$B14) -> 0.68589278 | I14: =(1+E14)^(-$B14) -> 0.82707326 | K14: =G14/G13 -> 0.97411622 | L14: =H14/H13 -> 0.96817406 | M14: =I14/I13 -> 0.97931931 | O14: =-LN(K14) -> 0.02622466 | P14: =-LN(L14) -> 0.032343392 | Q14: =-LN(M14) -> 0.020897529
B15: 12 | C15: 0.02487 | D15: 0.03487 | E15: 0.01766 | G15: =(1+C15)^(-$B15) -> 0.74468847 | H15: =(1+D15)^(-$B15) -> 0.66278158 | I15: =(1+E15)^(-$B15) -> 0.81052711 | K15: =G15/G14 -> 0.97573351 | L15: =H15/H14 -> 0.96630495 | M15: =I15/I14 -> 0.97999434 | O15: =-LN(K15) -> 0.024565775 | P15: =-LN(L15) -> 0.034275815 | Q15: =-LN(M15) -> 0.020208484
... B153: 150 | C153: 0.03121 | D153: 0.04121 | E153: 0.02497 | G153: =(1+C153)^(-$B153) -> 0.0099525099 | H153: =(1+D153)^(-$B153) -> 0.0023401862 | I153: =(1+E153)^(-$B153) -> 0.024735852 | K153: =G153/G152 -> 0.96833441 | L153: =H153/H152 -> 0.95904764 | M153: =I153/I152 -> 0.97422105 | O153: =-LN(K153) -> 0.032177782 | P153: =-LN(L153) -> 0.041814533 | Q153: =-LN(M153) -> 0.026117052

Sheet LIFE TABLE MALE FEMALE
A1: Tavole di mortalità della popolazione residente Italia - Maschi e femmine - Anno 2022
A2: Età x | B2: Sopravviventi lx | C2: Decessi dx | D2: Probabilità di morte (per mille) qx | E2: Anni vissuti Lx | F2: Probabilità prospettive di sopravvivenza Px | G2: Speranza di vita ex
A3: 0 | B3: 100000 | C3: 235 | D3: 2.34568 | E3: 99779 | F3: 0.999774 | G3: 82.64
A4: 1 | B4: 99765 | C4: 17 | D4: 0.17468 | E4: 99757 | F4: 0.9998499 | G4: 81.833
A5: 2 | B5: 99748 | C5: 13 | D5: 0.12547 | E5: 99742 | F5: 0.9998901 | G5: 80.847
A6: 3 | B6: 99735 | C6: 9 | D6: 0.09435 | E6: 99731 | F6: 0.9999149 | G6: 79.857
A7: 4 | B7: 99726 | C7: 8 | D7: 0.0759 | E7: 99722 | F7: 0.9999257 | G7: 78.865
A8: 5 | B8: 99719 | C8: 7 | D8: 0.07265 | E8: 99715 | F8: 0.9999279 | G8: 77.87
A9: 6 | B9: 99711 | C9: 7 | D9: 0.07149 | E9: 99708 | F9: 0.9999291 | G9: 76.876
A10: 7 | B10: 99704 | C10: 7 | D10: 0.0704 | E10: 99701 | F10: 0.999933 | G10: 75.882
A11: 8 | B11: 99697 | C11: 6 | D11: 0.06364 | E11: 99694 | F11: 0.9999357 | G11: 74.887
A12: 9 | B12: 99691 | C12: 6 | D12: 0.06498 | E12: 99688 | F12: 0.999934 | G12: 73.892
A13: 10 | B13: 99684 | C13: 7 | D13: 0.06693 | E13: 99681 | F13: 0.9999318 | G13: 72.896
A14: 11 | B14: 99678 | C14: 7 | D14: 0.06941 | E14: 99674 | F14: 0.9999278 | G14: 71.901
... A122: 119 | B122: 0 | C122: 0 | D122: 887.47597 | E122: 0 | F122: 0.1114 | G122: 0.625

Sheet LIFE TABLE MALE
A1: Tavole di mortalità della popolazione residente Italia - Maschi - Anno 2022
A2: Età x | B2: Sopravviventi lx | C2: Decessi dx | D2: Probabilità di morte (per mille) qx | E2: Anni vissuti Lx | F2: Probabilità prospettive di sopravvivenza Px | G2: Speranza di vita ex
A3: 0 | B3: 100000 | C3: 249 | D3: 2.49291 | E3: 99765 | F3: 0.9997548 | G3: 80.59
A4: 1 | B4: 99751 | C4: 20 | D4: 0.19564 | E4: 99741 | F4: 0.9998316 | G4: 79.79
A5: 2 | B5: 99731 | C5: 14 | D5: 0.14114 | E5: 99724 | F5: 0.999876 | G5: 78.805
A6: 3 | B6: 99717 | C6: 11 | D6: 0.10689 | E6: 99712 | F6: 0.9999034 | G6: 77.816
A7: 4 | B7: 99706 | C7: 9 | D7: 0.08633 | E7: 99702 | F7: 0.999914 | G7: 76.825
A8: 5 | B8: 99698 | C8: 9 | D8: 0.08565 | E8: 99694 | F8: 0.9999161 | G8: 75.831
A9: 6 | B9: 99689 | C9: 8 | D9: 0.08209 | E9: 99685 | F9: 0.9999203 | G9: 74.838
A10: 7 | B10: 99681 | C10: 8 | D10: 0.07729 | E10: 99677 | F10: 0.9999288 | G10: 73.844
A11: 8 | B11: 99673 | C11: 6 | D11: 0.0651 | E11: 99670 | F11: 0.9999347 | G11: 72.849
A12: 9 | B12: 99667 | C12: 7 | D12: 0.06556 | E12: 99664 | F12: 0.9999329 | G12: 71.854
A13: 10 | B13: 99660 | C13: 7 | D13: 0.0686 | E13: 99657 | F13: 0.999929 | G13: 70.859
A14: 11 | B14: 99654 | C14: 7 | D14: 0.07336 | E14: 99650 | F14: 0.9999226 | G14: 69.864
... A122: 119 | B122: 0 | C122: 0 | D122: 926.04048 | E122: 0 | F122: 0.0734327 | G122: 0.579

Sheet DATA
A1: DATA | D1: STRESS
A2: F0 | B2: 100000 | D2: Equity stress type 1 | E2: 0.39
A3: C0 | B3: 100000 | D3: Equity stress type 2 | E3: 0.49
A4: Sigma_Eq | B4: 0.2 | D4: Property stress | E4: 0.25
A5: Sigma_Pr | B5: 0.1 | D5: Lapse up | E5: 0.225
A6: Reg_Ded | B6: 0.022 | D6: Lapse down | E6: 0.075
A7: Lapse Rate | B7: 0.15
A8: Expenses / per year | B8: 50
A9: Inflation (flat ann rate) | B9: 0.02
A10: T (years) | B10: 50
A11: x | B11: 60
A12: Commissions | B12: 0.014

Sheet BASE
B1: EQUITY | C1: PROPERTY | D1: ASSET | E1: SURVIVAL PROB | F1: non LAPSE PROB | G1: C lapse | H1: C death | I1: LIAB LAPSE | J1: LIAB DEATH | K1: LIAB SURVIVE | L1: EXPENSES | M1: EQ COMMISSIONS | N1: PR COMMISSIONS | O1: TOT COMMISSIONS | P1: COMMISSIONS LIAB | Q1: DISCOUNTS | R1: TOT LIAB | S1: TOT LIAB DISC | T1: PROFIT PR | U1: PROFIT EQ | V1: TOT PROFIT | W1: PROFIT LIAB | X1: PROFIT LIAB DISCOUNTED
A2: 0 | B2: =DATA!B2*0.8 -> 80000 | C2: =DATA!B2*0.2 -> 20000 | D2: =B2+C2 -> 100000 | E2: =1 -> 1 | F2: =1 -> 1 | G2: =D2-20 -> 99980 | H2: =MAX(D2,DATA!$B$3) -> 100000 | M2: =B2 -> 80000 | N2: =C2 -> 20000 | Q2: =RATES!G3 -> 1
A3: 1 | B3: =B2*EXP(RATES!O4)*(1-DATA!$B$6) -> 80989.354 | C3: =C2*EXP(RATES!O4)*(1-DATA!$B$6) -> 20247.338 | D3: =B3+C3 -> 101236.69 | E3: =E2*(1-'LIFE TABLE MALE'!D63/1000) -> 0.99353213 | F3: =F2*(1-0.15) -> 0.85 | G3: =D3-20 -> 101216.69 | H3: =MAX(D3,DATA!$B$3) -> 101236.69 | I3: =G3*DATA!$B$7*F2*E3 -> 15084.305 | J3: =H3*'LIFE TABLE MALE'!D63/1000*F2*E2 -> 654.78576 | K3: =0 -> 0 | L3: =DATA!$B$8*((1+DATA!$B$9)^A2)*F3*E3 -> 42.225116 | M3: =B2*EXP(RATES!O4)*(DATA!$B$12) -> 1159.3568 | N3: =C2*EXP(RATES!O4)*(DATA!$B$12) -> 289.8392 | O3: =M3+N3 -> 1449.196 | P3: =O3*E3*F3 -> 1223.8494 | Q3: =RATES!G4 -> 0.9660529 | R3: =P3+L3+K3+J3+I3 -> 17005.166 | S3: =R3*Q3 -> 16427.89 | T3: =C2*EXP(RATES!O4)*(DATA!$B$6-DATA!$B$12) -> 165.6224 | U3: =B2*EXP(RATES!O4)*(DATA!$B$6-DATA!$B$12) -> 662.4896 | V3: =T3+U3 -> 828.112 | W3: =V3*E3*F3 -> 699.3425 | X3: =W3*BASE!Q3 -> 675.60185
A4: 2 | B4: =B3*EXP(RATES!O5)*(1-DATA!$B$6) -> 81233.889 | C4: =C3*EXP(RATES!O5)*(1-DATA!$B$6) -> 20308.472 | D4: =B4+C4 -> 101542.36 | E4: =E3*(1-'LIFE TABLE MALE'!D64/1000) -> 0.98647779 | F4: =F3*(1-0.15) -> 0.7225 | G4: =D4-20 -> 101522.36 | H4: =MAX(D4,DATA!$B$3) -> 101542.36 | I4: =G4*DATA!$B$7*F3*E4 -> 12769.068 | J4: =H4*'LIFE TABLE MALE'!D64/1000*F3*E3 -> 608.86689 | K4: =0 -> 0 | L4: =DATA!$B$8*((1+DATA!$B$9)^A3)*F4*E4 -> 36.34924 | M4: =B3*EXP(RATES!O5)*(DATA!$B$12) -> 1162.8573 | N4: =C3*EXP(RATES!O5)*(DATA!$B$12) -> 290.71433 | O4: =M4+N4 -> 1453.5716 | P4: =O4*E4*F4 -> 1036.0044 | Q4: =RATES!G5 -> 0.94195564 | R4: =P4+L4+K4+J4+I4 -> 14450.289 | S4: =R4*Q4 -> 13611.531 | T4: =C3*EXP(RATES!O5)*(DATA!$B$6-DATA!$B$12) -> 166.12247 | U4: =B3*EXP(RATES!O5)*(DATA!$B$6-DATA!$B$12) -> 664.48989 | V4: =T4+U4 -> 830.61237 | W4: =V4*E4*F4 -> 592.00252 | X4: =W4*BASE!Q4 -> 557.64011
A5: 3 | B5: =B4*EXP(RATES!O6)*(1-DATA!$B$6) -> 81258.803 | C5: =C4*EXP(RATES!O6)*(1-DATA!$B$6) -> 20314.701 | D5: =B5+C5 -> 101573.5 | E5: =E4*(1-'LIFE TABLE MALE'!D65/1000) -> 0.97876837 | F5: =F4*(1-0.15) -> 0.614125 | G5: =D5-20 -> 101553.5 | H5: =MAX(D5,DATA!$B$3) -> 101573.5 | I5: =G5*DATA!$B$7*F4*E5 -> 10772.189 | J5: =H5*'LIFE TABLE MALE'!D65/1000*F4*E4 -> 565.77029 | K5: =0 -> 0 | L5: =DATA!$B$8*((1+DATA!$B$9)^A4)*F5*E5 -> 31.2685 | M5: =B4*EXP(RATES!O6)*(DATA!$B$12) -> 1163.2139 | N5: =C4*EXP(RATES!O6)*(DATA!$B$12) -> 290.80349 | O5: =M5+N5 -> 1454.0174 | P5: =O5*E5*F5 -> 873.98971 | Q5: =RATES!G6 -> 0.92095017 | R5: =P5+L5+K5+J5+I5 -> 12243.217 | S5: =R5*Q5 -> 11275.393 | T5: =C4*EXP(RATES!O6)*(DATA!$B$6-DATA!$B$12) -> 166.17342 | U5: =B4*EXP(RATES!O6)*(DATA!$B$6-DATA!$B$12) -> 664.69368 | V5: =T5+U5 -> 830.86711 | W5: =V5*E5*F5 -> 499.42269 | X5: =W5*BASE!Q5 -> 459.94341
A6: 4 | B6: =B5*EXP(RATES!O7)*(1-DATA!$B$6) -> 81219.667 | C6: =C5*EXP(RATES!O7)*(1-DATA!$B$6) -> 20304.917 | D6: =B6+C6 -> 101524.58 | E6: =E5*(1-'LIFE TABLE MALE'!D66/1000) -> 0.97028747 | F6: =F5*(1-0.15) -> 0.52200625 | G6: =D6-20 -> 101504.58 | H6: =MAX(D6,DATA!$B$3) -> 101524.58 | I6: =G6*DATA!$B$7*F5*E6 -> 9072.6491 | J6: =H6*'LIFE TABLE MALE'!D66/1000*F5*E5 -> 528.77385 | K6: =0 -> 0 | L6: =DATA!$B$8*((1+DATA!$B$9)^A5)*F6*E6 -> 26.874887 | M6: =B5*EXP(RATES!O7)*(DATA!$B$12) -> 1162.6537 | N6: =C5*EXP(RATES!O7)*(DATA!$B$12) -> 290.66343 | O6: =M6+N6 -> 1453.3171 | P6: =O6*E6*F6 -> 736.0995 | Q6: =RATES!G7 -> 0.90112326 | R6: =P6+L6+K6+J6+I6 -> 10364.397 | S6: =R6*Q6 -> 9339.5996 | T6: =C5*EXP(RATES!O7)*(DATA!$B$6-DATA!$B$12) -> 166.09339 | U6: =B5*EXP(RATES!O7)*(DATA!$B$6-DATA!$B$12) -> 664.37355 | V6: =T6+U6 -> 830.46694 | W6: =V6*E6*F6 -> 420.62829 | X6: =W6*BASE!Q6 -> 379.03794
A7: 5 | B7: =B6*EXP(RATES!O8)*(1-DATA!$B$6) -> 81178.572 | C7: =C6*EXP(RATES!O8)*(1-DATA!$B$6) -> 20294.643 | D7: =B7+C7 -> 101473.22 | E7: =E6*(1-'LIFE TABLE MALE'!D67/1000) -> 0.96092158 | F7: =F6*(1-0.15) -> 0.44370531 | G7: =D7-20 -> 101453.22 | H7: =MAX(D7,DATA!$B$3) -> 101473.22 | I7: =G7*DATA!$B$7*F6*E7 -> 7633.4475 | J7: =H7*'LIFE TABLE MALE'!D67/1000*F6*E6 -> 496.10815 | K7: =0 -> 0 | L7: =DATA!$B$8*((1+DATA!$B$9)^A6)*F7*E7 -> 23.075614 | M7: =B6*EXP(RATES!O8)*(DATA!$B$12) -> 1162.0655 | N7: =C6*EXP(RATES!O8)*(DATA!$B$12) -> 290.51636 | O7: =M7+N7 -> 1452.5818 | P7: =O7*E7*F7 -> 619.33151 | Q7: =RATES!G8 -> 0.88174469 | R7: =P7+L7+K7+J7+I7 -> 8771.9628 | S7: =R7*Q7 -> 7734.6316 | T7: =C6*EXP(RATES!O8)*(DATA!$B$6-DATA!$B$12) -> 166.00935 | U7: =B6*EXP(RATES!O8)*(DATA!$B$6-DATA!$B$12) -> 664.0374 | V7: =T7+U7 -> 830.04675 | W7: =V7*E7*F7 -> 353.90372 | X7: =W7*BASE!Q7 -> 312.05273
A8: 6 | B8: =B7*EXP(RATES!O9)*(1-DATA!$B$6) -> 81192.731 | C8: =C7*EXP(RATES!O9)*(1-DATA!$B$6) -> 20298.183 | D8: =B8+C8 -> 101490.91 | E8: =E7*(1-'LIFE TABLE MALE'!D68/1000) -> 0.95054817 | F8: =F7*(1-0.15) -> 0.37714952 | G8: =D8-20 -> 101470.91 | H8: =MAX(D8,DATA!$B$3) -> 101490.91 | I8: =G8*DATA!$B$7*F7*E8 -> 6419.5057 | J8: =H8*'LIFE TABLE MALE'!D68/1000*F7*E7 -> 467.1359 | K8: =0 -> 0 | L8: =DATA!$B$8*((1+DATA!$B$9)^A7)*F8*E8 -> 19.790581 | M8: =B7*EXP(RATES!O9)*(DATA!$B$12) -> 1162.2681 | N8: =C7*EXP(RATES!O9)*(DATA!$B$12) -> 290.56703 | O8: =M8+N8 -> 1452.8352 | P8: =O8*E8*F8 -> 520.83964 | Q8: =RATES!G9 -> 0.86219592 | R8: =P8+L8+K8+J8+I8 -> 7427.2718 | S8: =R8*Q8 -> 6403.7635 | T8: =C7*EXP(RATES!O9)*(DATA!$B$6-DATA!$B$12) -> 166.03831 | U8: =B7*EXP(RATES!O9)*(DATA!$B$6-DATA!$B$12) -> 664.15322 | V8: =T8+U8 -> 830.19153 | W8: =V8*E8*F8 -> 297.62265 | X8: =W8*BASE!Q8 -> 256.60904
A9: 7 | B9: =B8*EXP(RATES!O10)*(1-DATA!$B$6) -> 81254.382 | C9: =C8*EXP(RATES!O10)*(1-DATA!$B$6) -> 20313.596 | D9: =B9+C9 -> 101567.98 | E9: =E8*(1-'LIFE TABLE MALE'!D69/1000) -> 0.93939989 | F9: =F8*(1-0.15) -> 0.32057709 | G9: =D9-20 -> 101547.98 | H9: =MAX(D9,DATA!$B$3) -> 101567.98 | I9: =G9*DATA!$B$7*F8*E9 -> 5396.6791 | J9: =H9*'LIFE TABLE MALE'!D69/1000*F8*E8 -> 427.04936 | K9: =0 -> 0 | L9: =DATA!$B$8*((1+DATA!$B$9)^A8)*F9*E9 -> 16.957195 | M9: =B8*EXP(RATES!O10)*(DATA!$B$12) -> 1163.1507 | N9: =C8*EXP(RATES!O10)*(DATA!$B$12) -> 290.78767 | O9: =M9+N9 -> 1453.9383 | P9: =O9*E9*F9 -> 437.85365 | Q9: =RATES!G10 -> 0.84258782 | R9: =P9+L9+K9+J9+I9 -> 6278.5393 | S9: =R9*Q9 -> 5290.2208 | T9: =C8*EXP(RATES!O10)*(DATA!$B$6-DATA!$B$12) -> 166.16438 | U9: =B8*EXP(RATES!O10)*(DATA!$B$6-DATA!$B$12) -> 664.65752 | V9: =T9+U9 -> 830.8219 | W9: =V9*E9*F9 -> 250.20208 | X9: =W9*BASE!Q9 -> 210.81723
A10: 8 | B10: =B9*EXP(RATES!O11)*(1-DATA!$B$6) -> 81365.273 | C10: =C9*EXP(RATES!O11)*(1-DATA!$B$6) -> 20341.318 | D10: =B10+C10 -> 101706.59 | E10: =E9*(1-'LIFE TABLE MALE'!D70/1000) -> 0.92737751 | F10: =F9*(1-0.15) -> 0.27249053 | G10: =D10-20 -> 101686.59 | H10: =MAX(D10,DATA!$B$3) -> 101706.59 | I10: =G10*DATA!$B$7*F9*E10 -> 4534.6523 | J10: =H10*'LIFE TABLE MALE'!D70/1000*F9*E9 -> 391.98744 | K10: =0 -> 0 | L10: =DATA!$B$8*((1+DATA!$B$9)^A9)*F10*E10 -> 14.513734 | M10: =B9*EXP(RATES!O11)*(DATA!$B$12) -> 1164.7381 | N10: =C9*EXP(RATES!O11)*(DATA!$B$12) -> 291.18452 | O10: =M10+N10 -> 1455.9226 | P10: =O10*E10*F10 -> 367.91394 | Q10: =RATES!G11 -> 0.82292781 | R10: =P10+L10+K10+J10+I10 -> 5309.0674 | S10: =R10*Q10 -> 4368.9792 | T10: =C9*EXP(RATES!O11)*(DATA!$B$6-DATA!$B$12) -> 166.39115 | U10: =B9*EXP(RATES!O11)*(DATA!$B$6-DATA!$B$12) -> 665.56461 | V10: =T10+U10 -> 831.95576 | W10: =V10*E10*F10 -> 210.23654 | X10: =W10*BASE!Q10 -> 173.00949
A11: 9 | B11: =B10*EXP(RATES!O12)*(1-DATA!$B$6) -> 81523.24 | C11: =C10*EXP(RATES!O12)*(1-DATA!$B$6) -> 20380.81 | D11: =B11+C11 -> 101904.05 | E11: =E10*(1-'LIFE TABLE MALE'!D71/1000) -> 0.91441742 | F11: =F10*(1-0.15) -> 0.23161695 | G11: =D11-20 -> 101884.05 | H11: =MAX(D11,DATA!$B$3) -> 101904.05 | I11: =G11*DATA!$B$7*F10*E11 -> 3807.9686 | J11: =H11*'LIFE TABLE MALE'!D71/1000*F10*E10 -> 359.87437 | K11: =0 -> 0 | L11: =DATA!$B$8*((1+DATA!$B$9)^A10)*F11*E11 -> 12.407555 | M11: =B10*EXP(RATES!O12)*(DATA!$B$12) -> 1166.9993 | N11: =C10*EXP(RATES!O12)*(DATA!$B$12) -> 291.74984 | O11: =M11+N11 -> 1458.7492 | P11: =O11*E11*F11 -> 308.95516 | Q11: =RATES!G12 -> 0.8032639 | R11: =P11+L11+K11+J11+I11 -> 4489.2057 | S11: =R11*Q11 -> 3606.0168 | T11: =C10*EXP(RATES!O12)*(DATA!$B$6-DATA!$B$12) -> 166.71419 | U11: =B10*EXP(RATES!O12)*(DATA!$B$6-DATA!$B$12) -> 666.85677 | V11: =T11+U11 -> 833.57096 | W11: =V11*E11*F11 -> 176.5458 | X11: =W11*BASE!Q11 -> 141.81287
A12: 10 | B12: =B11*EXP(RATES!O13)*(1-DATA!$B$6) -> 81742.12 | C12: =C11*EXP(RATES!O13)*(1-DATA!$B$6) -> 20435.53 | D12: =B12+C12 -> 102177.65 | E12: =E11*(1-'LIFE TABLE MALE'!D72/1000) -> 0.9000976 | F12: =F11*(1-0.15) -> 0.1968744 | G12: =D12-20 -> 102157.65 | H12: =MAX(D12,DATA!$B$3) -> 102177.65 | I12: =G12*DATA!$B$7*F11*E12 -> 3194.6412 | J12: =H12*'LIFE TABLE MALE'!D72/1000*F11*E11 -> 338.894 | K12: =0 -> 0 | L12: =DATA!$B$8*((1+DATA!$B$9)^A11)*F12*E12 -> 10.588889 | M12: =B11*EXP(RATES!O13)*(DATA!$B$12) -> 1170.1326 | N12: =C11*EXP(RATES!O13)*(DATA!$B$12) -> 292.53315 | O12: =M12+N12 -> 1462.6657 | P12: =O12*E12*F12 -> 259.19341 | Q12: =RATES!G13 -> 0.78348852 | R12: =P12+L12+K12+J12+I12 -> 3803.3175 | S12: =R12*Q12 -> 2979.8556 | T12: =C11*EXP(RATES!O13)*(DATA!$B$6-DATA!$B$12) -> 167.1618 | U12: =B11*EXP(RATES!O13)*(DATA!$B$6-DATA!$B$12) -> 668.6472 | V12: =T12+U12 -> 835.809 | W12: =V12*E12*F12 -> 148.11052 | X12: =W12*BASE!Q12 -> 116.04289
A13: 11 | B13: =B12*EXP(RATES!O14)*(1-DATA!$B$6) -> 82068.024 | C13: =C12*EXP(RATES!O14)*(1-DATA!$B$6) -> 20517.006 | D13: =B13+C13 -> 102585.03 | E13: =E12*(1-'LIFE TABLE MALE'!D73/1000) -> 0.88436967 | F13: =F12*(1-0.15) -> 0.16734324 | G13: =D13-20 -> 102565.03 | H13: =MAX(D13,DATA!$B$3) -> 102585.03 | I13: =G13*DATA!$B$7*F12*E13 -> 2678.6358 | J13: =H13*'LIFE TABLE MALE'!D73/1000*F12*E12 -> 317.64699 | K13: =0 -> 0 | L13: =DATA!$B$8*((1+DATA!$B$9)^A12)*F13*E13 -> 9.0201497 | M13: =B12*EXP(RATES!O14)*(DATA!$B$12) -> 1174.7979 | N13: =C12*EXP(RATES!O14)*(DATA!$B$12) -> 293.69947 | O13: =M13+N13 -> 1468.4974 | P13: =O13*E13*F13 -> 217.32775 | Q13: =RATES!G14 -> 0.76320888 | R13: =P13+L13+K13+J13+I13 -> 3222.6307 | S13: =R13*Q13 -> 2459.5403 | T13: =C12*EXP(RATES!O14)*(DATA!$B$6-DATA!$B$12) -> 167.82827 | U13: =B12*EXP(RATES!O14)*(DATA!$B$6-DATA!$B$12) -> 671.31308 | V13: =T13+U13 -> 839.14135 | W13: =V13*E13*F13 -> 124.18729 | X13: =W13*BASE!Q13 -> 94.780841
A14: 12 | B14: =B13*EXP(RATES!O15)*(1-DATA!$B$6) -> 82258.657 | C14: =C13*EXP(RATES!O15)*(1-DATA!$B$6) -> 20564.664 | D14: =B14+C14 -> 102823.32 | E14: =E13*(1-'LIFE TABLE MALE'!D74/1000) -> 0.86691444 | F14: =F13*(1-0.15) -> 0.14224176 | G14: =D14-20 -> 102803.32 | H14: =MAX(D14,DATA!$B$3) -> 102823.32 | I14: =G14*DATA!$B$7*F13*E14 -> 2237.0867 | J14: =H14*'LIFE TABLE MALE'!D74/1000*F13*E13 -> 300.34842 | K14: =0 -> 0 | L14: =DATA!$B$8*((1+DATA!$B$9)^A13)*F14*E14 -> 7.6661134 | M14: =B13*EXP(RATES!O15)*(DATA!$B$12) -> 1177.5268 | N14: =C13*EXP(RATES!O15)*(DATA!$B$12) -> 294.3817 | O14: =M14+N14 -> 1471.9085 | P14: =O14*E14*F14 -> 181.50314 | Q14: =RATES!G15 -> 0.74468847 | R14: =P14+L14+K14+J14+I14 -> 2726.6044 | S14: =R14*Q14 -> 2030.4709 | T14: =C13*EXP(RATES!O15)*(DATA!$B$6-DATA!$B$12) -> 168.21811 | U14: =B13*EXP(RATES!O15)*(DATA!$B$6-DATA!$B$12) -> 672.87245 | V14: =T14+U14 -> 841.09056 | W14: =V14*E14*F14 -> 103.71608 | X14: =W14*BASE!Q14 -> 77.236171
... A51: 49 | B51: =B50*EXP(RATES!O52)*(1-DATA!$B$6) -> 102111.48 | C51: =C50*EXP(RATES!O52)*(1-DATA!$B$6) -> 25527.869 | D51: =B51+C51 -> 127639.35 | E51: =E50*(1-'LIFE TABLE MALE'!D111/1000) -> 2.6221013e-06 | F51: =F50*(1-0.15) -> 0.00034795843 | G51: =D51-20 -> 127619.35 | H51: =MAX(D51,DATA!$B$3) -> 127639.35 | I51: =G51*DATA!$B$7*F50*E51 -> 2.0547816e-05 | J51: =H51*'LIFE TABLE MALE'!D111/1000*F50*E50 -> 0.00033735942 | K51: =0 -> 0 | L51: =DATA!$B$8*((1+DATA!$B$9)^A50)*F51*E51 -> 1.1801985e-07 | M51: =B50*EXP(RATES!O52)*(DATA!$B$12) -> 1461.7185 | N51: =C50*EXP(RATES!O52)*(DATA!$B$12) -> 365.42962 | O51: =M51+N51 -> 1827.1481 | P51: =O51*E51*F51 -> 1.6670575e-06 | Q51: =RATES!G52 -> 0.26340215 | R51: =P51+L51+K51+J51+I51 -> 0.00035969231 | S51: =R51*Q51 -> 9.4743728e-05 | T51: =C50*EXP(RATES!O52)*(DATA!$B$6-DATA!$B$12) -> 208.81693 | U51: =B50*EXP(RATES!O52)*(DATA!$B$6-DATA!$B$12) -> 835.2677 | V51: =T51+U51 -> 1044.0846 | W51: =V51*E51*F51 -> 9.5260428e-07 | X51: =W51*BASE!Q51 -> 2.5091802e-07
A52: 50 | B52: =B51*EXP(RATES!O53)*(1-DATA!$B$6) -> 103172 | C52: =C51*EXP(RATES!O53)*(1-DATA!$B$6) -> 25793 | D52: =B52+C52 -> 128965 | E52: =E51*(1-'LIFE TABLE MALE'!D112/1000) -> 6.7948871e-07 | F52: =F51*(1-0.15) -> 0.00029576466 | G52: =D52-20 -> 128945 | H52: =MAX(D52,DATA!$B$3) -> 128965 | I52: =G52*DATA!$B$7*F51*E52 -> 4.5730439e-06 | J52: =H52*'LIFE TABLE MALE'!D112/1000*F51*E51 -> 8.7173688e-05 | K52: =E52*D52*F52 -> 2.5917935e-05 | L52: =DATA!$B$8*((1+DATA!$B$9)^A51)*F52*E52 -> 2.6515935e-08 | M52: =B51*EXP(RATES!O53)*(DATA!$B$12) -> 1476.8998 | N52: =C51*EXP(RATES!O53)*(DATA!$B$12) -> 369.22495 | O52: =M52+N52 -> 1846.1247 | P52: =O52*E52*F52 -> 3.7101338e-07 | Q52: =RATES!G53 -> 0.25495931 | R52: =P52+L52+K52+J52+I52 -> 0.0001180622 | S52: =R52*Q52 -> 3.0101056e-05 | T52: =C51*EXP(RATES!O53)*(DATA!$B$6-DATA!$B$12) -> 210.98568 | U52: =B51*EXP(RATES!O53)*(DATA!$B$6-DATA!$B$12) -> 843.94273 | V52: =T52+U52 -> 1054.9284 | W52: =V52*E52*F52 -> 2.1200765e-07 | X52: =W52*BASE!Q52 -> 5.4053324e-08
P56: LIABILITIES | Q56: =SUM(S3:S52) -> 94493.616 | T56: BEL COMPONENTS
P57: BOF | Q57: =DATA!B2-Q56 -> 5506.3842 | T57: DEATH | U57: =SUMPRODUCT(J3:J52,Q3:Q52) -> 6428.626
T58: LAPSE | U58: =SUMPRODUCT(I3:I52,Q3:Q52) -> 81227.1
P59: DURATION | Q59: =SUMPRODUCT(S3:S52,A3:A52)/SUM(S3:S52) -> 5.6130734 | T59: EXPENSES | U59: =SUMPRODUCT(L3:L52,Q3:Q52) -> 247.61987
T60: COMMISSIONS | U60: =SUMPRODUCT(P3:P52,Q3:Q52) -> 6590.2696
P61: PVFP | Q61: =SUM(X3:X52) -> 3765.8683
P62: LEAK | Q62: =D2-Q56-Q61 -> 1740.5158
P63: PVFP PROXY | Q63: =(DATA!B6-DATA!B12)*DATA!B2*Q59 -> 4490.4587

Sheet EQ STRESS 1
B1: EQUITY | C1: PROPERTY | D1: ASSET | E1: SURVIVAL PROB | F1: non LAPSE PROB | G1: C lapse | H1: C death | I1: LIAB LAPSE | J1: LIAB DEATH | K1: LIAB SURVIVE | L1: EXPENSES | M1: EQ COMMISSIONS | N1: PR COMMISSIONS | O1: TOT COMMISSIONS | P1: COMMISSIONS LIAB | Q1: DISCOUNTS | R1: TOT LIAB | S1: TOT LIAB DISC | T1: PROFIT PR | U1: PROFIT EQ | V1: TOT PROFIT | W1: PROFIT LIAB
A2: 0 | B2: =DATA!B2*0.8*(1-DATA!E2) -> 48800 | C2: =DATA!B2*0.2 -> 20000 | D2: =B2+C2 -> 68800 | E2: =1 -> 1 | F2: =1 -> 1 | G2: =D2-20 -> 68780 | H2: =MAX(D2,$B$2+$C$2) -> 68800 | M2: =B2 -> 48800 | N2: =C2 -> 20000 | Q2: =RATES!G3 -> 1
A3: 1 | B3: =B2*EXP(RATES!O4)*(1-DATA!$B$6) -> 49403.506 | C3: =C2*EXP(RATES!O4)*(1-DATA!$B$6) -> 20247.338 | D3: =B3+C3 -> 69650.844 | E3: =E2*(1-'LIFE TABLE MALE'!D63/1000) -> 0.99353213 | F3: =F2*(1-0.15) -> 0.85 | G3: =D3-20 -> 69630.844 | H3: =MAX(D3,$B$2+$C$2) -> 69650.844 | I3: =G3*DATA!$B$7*F2*E3 -> 10377.072 | J3: =H3*'LIFE TABLE MALE'!D63/1000*F2*E2 -> 450.49261 | K3: =0 -> 0 | L3: =DATA!$B$8*((1+DATA!$B$9)^A2)*F3*E3 -> 42.225116 | M3: =B2*EXP(RATES!O4)*(DATA!$B$12) -> 707.20765 | N3: =C2*EXP(RATES!O4)*(DATA!$B$12) -> 289.8392 | O3: =M3+N3 -> 997.04685 | P3: =O3*E3*F3 -> 842.00837 | Q3: =RATES!G4 -> 0.9660529 | R3: =P3+L3+K3+J3+I3 -> 11711.798 | S3: =R3*Q3 -> 11314.217 | T3: =C2*EXP(RATES!O4)*(DATA!$B$6-DATA!$B$12) -> 165.6224 | U3: =B2*EXP(RATES!O4)*(DATA!$B$6-DATA!$B$12) -> 404.11866 | V3: =T3+U3 -> 569.74106 | W3: =V3*E3*F3 -> 481.14764
A4: 2 | B4: =B3*EXP(RATES!O5)*(1-DATA!$B$6) -> 49552.673 | C4: =C3*EXP(RATES!O5)*(1-DATA!$B$6) -> 20308.472 | D4: =B4+C4 -> 69861.145 | E4: =E3*(1-'LIFE TABLE MALE'!D64/1000) -> 0.98647779 | F4: =F3*(1-0.15) -> 0.7225 | G4: =D4-20 -> 69841.145 | H4: =MAX(D4,$B$2+$C$2) -> 69861.145 | I4: =G4*DATA!$B$7*F3*E4 -> 8784.3342 | J4: =H4*'LIFE TABLE MALE'!D64/1000*F3*E3 -> 418.90042 | K4: =0 -> 0 | L4: =DATA!$B$8*((1+DATA!$B$9)^A3)*F4*E4 -> 36.34924 | M4: =B3*EXP(RATES!O5)*(DATA!$B$12) -> 709.34296 | N4: =C3*EXP(RATES!O5)*(DATA!$B$12) -> 290.71433 | O4: =M4+N4 -> 1000.0573 | P4: =O4*E4*F4 -> 712.77104 | Q4: =RATES!G5 -> 0.94195564 | R4: =P4+L4+K4+J4+I4 -> 9952.3549 | S4: =R4*Q4 -> 9374.6768 | T4: =C3*EXP(RATES!O5)*(DATA!$B$6-DATA!$B$12) -> 166.12247 | U4: =B3*EXP(RATES!O5)*(DATA!$B$6-DATA!$B$12) -> 405.33883 | V4: =T4+U4 -> 571.46131 | W4: =V4*E4*F4 -> 407.29774
A5: 3 | B5: =B4*EXP(RATES!O6)*(1-DATA!$B$6) -> 49567.87 | C5: =C4*EXP(RATES!O6)*(1-DATA!$B$6) -> 20314.701 | D5: =B5+C5 -> 69882.571 | E5: =E4*(1-'LIFE TABLE MALE'!D65/1000) -> 0.97876837 | F5: =F4*(1-0.15) -> 0.614125 | G5: =D5-20 -> 69862.571 | H5: =MAX(D5,$B$2+$C$2) -> 69882.571 | I5: =G5*DATA!$B$7*F4*E5 -> 7410.6039 | J5: =H5*'LIFE TABLE MALE'!D65/1000*F4*E4 -> 389.24996 | K5: =0 -> 0 | L5: =DATA!$B$8*((1+DATA!$B$9)^A4)*F5*E5 -> 31.2685 | M5: =B4*EXP(RATES!O6)*(DATA!$B$12) -> 709.56051 | N5: =C4*EXP(RATES!O6)*(DATA!$B$12) -> 290.80349 | O5: =M5+N5 -> 1000.364 | P5: =O5*E5*F5 -> 601.30492 | Q5: =RATES!G6 -> 0.92095017 | R5: =P5+L5+K5+J5+I5 -> 8432.4272 | S5: =R5*Q5 -> 7765.8453 | T5: =C4*EXP(RATES!O6)*(DATA!$B$6-DATA!$B$12) -> 166.17342 | U5: =B4*EXP(RATES!O6)*(DATA!$B$6-DATA!$B$12) -> 405.46315 | V5: =T5+U5 -> 571.63657 | W5: =V5*E5*F5 -> 343.60281
A6: 4 | B6: =B5*EXP(RATES!O7)*(1-DATA!$B$6) -> 49543.997 | C6: =C5*EXP(RATES!O7)*(1-DATA!$B$6) -> 20304.917 | D6: =B6+C6 -> 69848.914 | E6: =E5*(1-'LIFE TABLE MALE'!D66/1000) -> 0.97028747 | F6: =F5*(1-0.15) -> 0.52200625 | G6: =D6-20 -> 69828.914 | H6: =MAX(D6,$B$2+$C$2) -> 69848.914 | I6: =G6*DATA!$B$7*F5*E6 -> 6241.4248 | J6: =H6*'LIFE TABLE MALE'!D66/1000*F5*E5 -> 363.79641 | K6: =0 -> 0 | L6: =DATA!$B$8*((1+DATA!$B$9)^A5)*F6*E6 -> 26.874887 | M6: =B5*EXP(RATES!O7)*(DATA!$B$12) -> 709.21877 | N6: =C5*EXP(RATES!O7)*(DATA!$B$12) -> 290.66343 | O6: =M6+N6 -> 999.8822 | P6: =O6*E6*F6 -> 506.43646 | Q6: =RATES!G7 -> 0.90112326 | R6: =P6+L6+K6+J6+I6 -> 7138.5326 | S6: =R6*Q6 -> 6432.6978 | T6: =C5*EXP(RATES!O7)*(DATA!$B$6-DATA!$B$12) -> 166.09339 | U6: =B5*EXP(RATES!O7)*(DATA!$B$6-DATA!$B$12) -> 405.26787 | V6: =T6+U6 -> 571.36126 | W6: =V6*E6*F6 -> 289.39226
A7: 5 | B7: =B6*EXP(RATES!O8)*(1-DATA!$B$6) -> 49518.929 | C7: =C6*EXP(RATES!O8)*(1-DATA!$B$6) -> 20294.643 | D7: =B7+C7 -> 69813.572 | E7: =E6*(1-'LIFE TABLE MALE'!D67/1000) -> 0.96092158 | F7: =F6*(1-0.15) -> 0.44370531 | G7: =D7-20 -> 69793.572 | H7: =MAX(D7,$B$2+$C$2) -> 69813.572 | I7: =G7*DATA!$B$7*F6*E7 -> 5251.3424 | J7: =H7*'LIFE TABLE MALE'!D67/1000*F6*E6 -> 341.3224 | K7: =0 -> 0 | L7: =DATA!$B$8*((1+DATA!$B$9)^A6)*F7*E7 -> 23.075614 | M7: =B6*EXP(RATES!O8)*(DATA!$B$12) -> 708.85993 | N7: =C6*EXP(RATES!O8)*(DATA!$B$12) -> 290.51636 | O7: =M7+N7 -> 999.37629 | P7: =O7*E7*F7 -> 426.10008 | Q7: =RATES!G8 -> 0.88174469 | R7: =P7+L7+K7+J7+I7 -> 6041.8405 | S7: =R7*Q7 -> 5327.3607 | T7: =C6*EXP(RATES!O8)*(DATA!$B$6-DATA!$B$12) -> 166.00935 | U7: =B6*EXP(RATES!O8)*(DATA!$B$6-DATA!$B$12) -> 405.06282 | V7: =T7+U7 -> 571.07217 | W7: =V7*E7*F7 -> 243.48576
A8: 6 | B8: =B7*EXP(RATES!O9)*(1-DATA!$B$6) -> 49527.566 | C8: =C7*EXP(RATES!O9)*(1-DATA!$B$6) -> 20298.183 | D8: =B8+C8 -> 69825.749 | E8: =E7*(1-'LIFE TABLE MALE'!D68/1000) -> 0.95054817 | F8: =F7*(1-0.15) -> 0.37714952 | G8: =D8-20 -> 69805.749 | H8: =MAX(D8,$B$2+$C$2) -> 69825.749 | I8: =G8*DATA!$B$7*F7*E8 -> 4416.2252 | J8: =H8*'LIFE TABLE MALE'!D68/1000*F7*E7 -> 321.3895 | K8: =0 -> 0 | L8: =DATA!$B$8*((1+DATA!$B$9)^A7)*F8*E8 -> 19.790581 | M8: =B7*EXP(RATES!O9)*(DATA!$B$12) -> 708.98356 | N8: =C7*EXP(RATES!O9)*(DATA!$B$12) -> 290.56703 | O8: =M8+N8 -> 999.5506 | P8: =O8*E8*F8 -> 358.33767 | Q8: =RATES!G9 -> 0.86219592 | R8: =P8+L8+K8+J8+I8 -> 5115.7429 | S8: =R8*Q8 -> 4410.7727 | T8: =C7*EXP(RATES!O9)*(DATA!$B$6-DATA!$B$12) -> 166.03831 | U8: =B7*EXP(RATES!O9)*(DATA!$B$6-DATA!$B$12) -> 405.13347 | V8: =T8+U8 -> 571.17177 | W8: =V8*E8*F8 -> 204.76438
A9: 7 | B9: =B8*EXP(RATES!O10)*(1-DATA!$B$6) -> 49565.173 | C9: =C8*EXP(RATES!O10)*(1-DATA!$B$6) -> 20313.596 | D9: =B9+C9 -> 69878.769 | E9: =E8*(1-'LIFE TABLE MALE'!D69/1000) -> 0.93939989 | F9: =F8*(1-0.15) -> 0.32057709 | G9: =D9-20 -> 69858.769 | H9: =MAX(D9,$B$2+$C$2) -> 69878.769 | I9: =G9*DATA!$B$7*F8*E9 -> 3712.5836 | J9: =H9*'LIFE TABLE MALE'!D69/1000*F8*E8 -> 293.80996 | K9: =0 -> 0 | L9: =DATA!$B$8*((1+DATA!$B$9)^A8)*F9*E9 -> 16.957195 | M9: =B8*EXP(RATES!O10)*(DATA!$B$12) -> 709.5219 | N9: =C8*EXP(RATES!O10)*(DATA!$B$12) -> 290.78767 | O9: =M9+N9 -> 1000.3096 | P9: =O9*E9*F9 -> 301.24331 | Q9: =RATES!G10 -> 0.84258782 | R9: =P9+L9+K9+J9+I9 -> 4324.5941 | S9: =R9*Q9 -> 3643.8503 | T9: =C8*EXP(RATES!O10)*(DATA!$B$6-DATA!$B$12) -> 166.16438 | U9: =B8*EXP(RATES!O10)*(DATA!$B$6-DATA!$B$12) -> 405.44109 | V9: =T9+U9 -> 571.60547 | W9: =V9*E9*F9 -> 172.13903
A10: 8 | B10: =B9*EXP(RATES!O11)*(1-DATA!$B$6) -> 49632.817 | C10: =C9*EXP(RATES!O11)*(1-DATA!$B$6) -> 20341.318 | D10: =B10+C10 -> 69974.135 | E10: =E9*(1-'LIFE TABLE MALE'!D70/1000) -> 0.92737751 | F10: =F9*(1-0.15) -> 0.27249053 | G10: =D10-20 -> 69954.135 | H10: =MAX(D10,$B$2+$C$2) -> 69974.135 | I10: =G10*DATA!$B$7*F9*E10 -> 3119.5625 | J10: =H10*'LIFE TABLE MALE'!D70/1000*F9*E9 -> 269.68736 | K10: =0 -> 0 | L10: =DATA!$B$8*((1+DATA!$B$9)^A9)*F10*E10 -> 14.513734 | M10: =B9*EXP(RATES!O11)*(DATA!$B$12) -> 710.49022 | N10: =C9*EXP(RATES!O11)*(DATA!$B$12) -> 291.18452 | O10: =M10+N10 -> 1001.6747 | P10: =O10*E10*F10 -> 253.12479 | Q10: =RATES!G11 -> 0.82292781 | R10: =P10+L10+K10+J10+I10 -> 3656.8884 | S10: =R10*Q10 -> 3009.3551 | T10: =C9*EXP(RATES!O11)*(DATA!$B$6-DATA!$B$12) -> 166.39115 | U10: =B9*EXP(RATES!O11)*(DATA!$B$6-DATA!$B$12) -> 405.99441 | V10: =T10+U10 -> 572.38556 | W10: =V10*E10*F10 -> 144.64274
A11: 9 | B11: =B10*EXP(RATES!O12)*(1-DATA!$B$6) -> 49729.177 | C11: =C10*EXP(RATES!O12)*(1-DATA!$B$6) -> 20380.81 | D11: =B11+C11 -> 70109.987 | E11: =E10*(1-'LIFE TABLE MALE'!D71/1000) -> 0.91441742 | F11: =F10*(1-0.15) -> 0.23161695 | G11: =D11-20 -> 70089.987 | H11: =MAX(D11,$B$2+$C$2) -> 70109.987 | I11: =G11*DATA!$B$7*F10*E11 -> 2619.6492 | J11: =H11*'LIFE TABLE MALE'!D71/1000*F10*E10 -> 247.59357 | K11: =0 -> 0 | L11: =DATA!$B$8*((1+DATA!$B$9)^A10)*F11*E11 -> 12.407555 | M11: =B10*EXP(RATES!O12)*(DATA!$B$12) -> 711.8696 | N11: =C10*EXP(RATES!O12)*(DATA!$B$12) -> 291.74984 | O11: =M11+N11 -> 1003.6194 | P11: =O11*E11*F11 -> 212.56115 | Q11: =RATES!G12 -> 0.8032639 | R11: =P11+L11+K11+J11+I11 -> 3092.2114 | S11: =R11*Q11 -> 2483.8618 | T11: =C10*EXP(RATES!O12)*(DATA!$B$6-DATA!$B$12) -> 166.71419 | U11: =B10*EXP(RATES!O12)*(DATA!$B$6-DATA!$B$12) -> 406.78263 | V11: =T11+U11 -> 573.49682 | W11: =V11*E11*F11 -> 121.46351
A12: 10 | B12: =B11*EXP(RATES!O13)*(1-DATA!$B$6) -> 49862.693 | C12: =C11*EXP(RATES!O13)*(1-DATA!$B$6) -> 20435.53 | D12: =B12+C12 -> 70298.223 | E12: =E11*(1-'LIFE TABLE MALE'!D72/1000) -> 0.9000976 | F12: =F11*(1-0.15) -> 0.1968744 | G12: =D12-20 -> 70278.223 | H12: =MAX(D12,$B$2+$C$2) -> 70298.223 | I12: =G12*DATA!$B$7*F11*E12 -> 2197.718 | J12: =H12*'LIFE TABLE MALE'!D72/1000*F11*E11 -> 233.15907 | K12: =0 -> 0 | L12: =DATA!$B$8*((1+DATA!$B$9)^A11)*F12*E12 -> 10.588889 | M12: =B11*EXP(RATES!O13)*(DATA!$B$12) -> 713.78088 | N12: =C11*EXP(RATES!O13)*(DATA!$B$12) -> 292.53315 | O12: =M12+N12 -> 1006.314 | P12: =O12*E12*F12 -> 178.32506 | Q12: =RATES!G13 -> 0.78348852 | R12: =P12+L12+K12+J12+I12 -> 2619.791 | S12: =R12*Q12 -> 2052.5762 | T12: =C11*EXP(RATES!O13)*(DATA!$B$6-DATA!$B$12) -> 167.1618 | U12: =B11*EXP(RATES!O13)*(DATA!$B$6-DATA!$B$12) -> 407.87479 | V12: =T12+U12 -> 575.03659 | W12: =V12*E12*F12 -> 101.90004
A13: 11 | B13: =B12*EXP(RATES!O14)*(1-DATA!$B$6) -> 50061.495 | C13: =C12*EXP(RATES!O14)*(1-DATA!$B$6) -> 20517.006 | D13: =B13+C13 -> 70578.501 | E13: =E12*(1-'LIFE TABLE MALE'!D73/1000) -> 0.88436967 | F13: =F12*(1-0.15) -> 0.16734324 | G13: =D13-20 -> 70558.501 | H13: =MAX(D13,$B$2+$C$2) -> 70578.501 | I13: =G13*DATA!$B$7*F12*E13 -> 1842.7385 | J13: =H13*'LIFE TABLE MALE'!D73/1000*F12*E12 -> 218.54113 | K13: =0 -> 0 | L13: =DATA!$B$8*((1+DATA!$B$9)^A12)*F13*E13 -> 9.0201497 | M13: =B12*EXP(RATES!O14)*(DATA!$B$12) -> 716.62671 | N13: =C12*EXP(RATES!O14)*(DATA!$B$12) -> 293.69947 | O13: =M13+N13 -> 1010.3262 | P13: =O13*E13*F13 -> 149.52149 | Q13: =RATES!G14 -> 0.76320888 | R13: =P13+L13+K13+J13+I13 -> 2219.8212 | S13: =R13*Q13 -> 1694.1873 | T13: =C12*EXP(RATES!O14)*(DATA!$B$6-DATA!$B$12) -> 167.82827 | U13: =B12*EXP(RATES!O14)*(DATA!$B$6-DATA!$B$12) -> 409.50098 | V13: =T13+U13 -> 577.32925 | W13: =V13*E13*F13 -> 85.440854
A14: 12 | B14: =B13*EXP(RATES!O15)*(1-DATA!$B$6) -> 50177.78 | C14: =C13*EXP(RATES!O15)*(1-DATA!$B$6) -> 20564.664 | D14: =B14+C14 -> 70742.445 | E14: =E13*(1-'LIFE TABLE MALE'!D74/1000) -> 0.86691444 | F14: =F13*(1-0.15) -> 0.14224176 | G14: =D14-20 -> 70722.445 | H14: =MAX(D14,$B$2+$C$2) -> 70742.445 | I14: =G14*DATA!$B$7*F13*E14 -> 1538.9799 | J14: =H14*'LIFE TABLE MALE'!D74/1000*F13*E13 -> 206.63971 | K14: =0 -> 0 | L14: =DATA!$B$8*((1+DATA!$B$9)^A13)*F14*E14 -> 7.6661134 | M14: =B13*EXP(RATES!O15)*(DATA!$B$12) -> 718.29134 | N14: =C13*EXP(RATES!O15)*(DATA!$B$12) -> 294.3817 | O14: =M14+N14 -> 1012.673 | P14: =O14*E14*F14 -> 124.87416 | Q14: =RATES!G15 -> 0.74468847 | R14: =P14+L14+K14+J14+I14 -> 1878.1599 | S14: =R14*Q14 -> 1398.644 | T14: =C13*EXP(RATES!O15)*(DATA!$B$6-DATA!$B$12) -> 168.21811 | U14: =B13*EXP(RATES!O15)*(DATA!$B$6-DATA!$B$12) -> 410.45219 | V14: =T14+U14 -> 578.6703 | W14: =V14*E14*F14 -> 71.356664
... A51: 49 | B51: =B50*EXP(RATES!O52)*(1-DATA!$B$6) -> 62288.001 | C51: =C50*EXP(RATES!O52)*(1-DATA!$B$6) -> 25527.869 | D51: =B51+C51 -> 87815.87 | E51: =E50*(1-'LIFE TABLE MALE'!D111/1000) -> 2.6221013e-06 | F51: =F50*(1-0.15) -> 0.00034795843 | G51: =D51-20 -> 87795.87 | H51: =MAX(D51,$B$2+$C$2) -> 87815.87 | I51: =G51*DATA!$B$7*F50*E51 -> 1.4135893e-05 | J51: =H51*'LIFE TABLE MALE'!D111/1000*F50*E50 -> 0.00023210328 | K51: =0 -> 0 | L51: =DATA!$B$8*((1+DATA!$B$9)^A50)*F51*E51 -> 1.1801985e-07 | M51: =B50*EXP(RATES!O52)*(DATA!$B$12) -> 891.64827 | N51: =C50*EXP(RATES!O52)*(DATA!$B$12) -> 365.42962 | O51: =M51+N51 -> 1257.0779 | P51: =O51*E51*F51 -> 1.1469356e-06 | Q51: =RATES!G52 -> 0.26340215 | R51: =P51+L51+K51+J51+I51 -> 0.00024750413 | S51: =R51*Q51 -> 6.5193119e-05 | T51: =C50*EXP(RATES!O52)*(DATA!$B$6-DATA!$B$12) -> 208.81693 | U51: =B50*EXP(RATES!O52)*(DATA!$B$6-DATA!$B$12) -> 509.5133 | V51: =T51+U51 -> 718.33022 | W51: =V51*E51*F51 -> 6.5539174e-07
A52: 50 | B52: =B51*EXP(RATES!O53)*(1-DATA!$B$6) -> 62934.92 | C52: =C51*EXP(RATES!O53)*(1-DATA!$B$6) -> 25793 | D52: =B52+C52 -> 88727.919 | E52: =E51*(1-'LIFE TABLE MALE'!D112/1000) -> 6.7948871e-07 | F52: =F51*(1-0.15) -> 0.00029576466 | G52: =D52-20 -> 88707.919 | H52: =MAX(D52,$B$2+$C$2) -> 88727.919 | I52: =G52*DATA!$B$7*F51*E52 -> 3.1460329e-06 | J52: =H52*'LIFE TABLE MALE'!D112/1000*F51*E51 -> 5.9975497e-05 | K52: =E52*D52*F52 -> 1.7831539e-05 | L52: =DATA!$B$8*((1+DATA!$B$9)^A51)*F52*E52 -> 2.6515935e-08 | M52: =B51*EXP(RATES!O53)*(DATA!$B$12) -> 900.90887 | N52: =C51*EXP(RATES!O53)*(DATA!$B$12) -> 369.22495 | O52: =M52+N52 -> 1270.1338 | P52: =O52*E52*F52 -> 2.552572e-07 | Q52: =RATES!G53 -> 0.25495931 | R52: =P52+L52+K52+J52+I52 -> 8.1234842e-05 | S52: =R52*Q52 -> 2.071158e-05 | T52: =C51*EXP(RATES!O53)*(DATA!$B$6-DATA!$B$12) -> 210.98568 | U52: =B51*EXP(RATES!O53)*(DATA!$B$6-DATA!$B$12) -> 514.80507 | V52: =T52+U52 -> 725.79075 | W52: =V52*E52*F52 -> 1.4586126e-07
P56: LIABILITIES | Q56: =SUM(S3:S52) -> 65083.882 | T56: BEL COMPONENTS
P57: BOF | Q57: =B2+C2-Q56 -> 3716.1178 | T57: DEATH | U57: =SUMPRODUCT(J3:J52,Q3:Q52) -> 4422.8947
T58: LAPSE | U58: =SUMPRODUCT(I3:I52,Q3:Q52) -> 55879.262
P59: DURATION | Q59: =SUMPRODUCT(S3:S52,A3:A52)/SUM(S3:S52) -> 5.6132956 | T59: EXPENSES | U59: =SUMPRODUCT(L3:L52,Q3:Q52) -> 247.61987
T60: COMMISSIONS | U60: =SUMPRODUCT(P3:P52,Q3:Q52) -> 4534.1055

Sheet PROPERTY STRESS
B1: EQUITY | C1: PROPERTY | D1: ASSET | E1: SURVIVAL PROB | F1: non LAPSE PROB | G1: C lapse | H1: C death | I1: LIAB LAPSE | J1: LIAB DEATH | K1: LIAB SURVIVE | L1: EXPENSES | M1: EQ COMMISSIONS | N1: PR COMMISSIONS | O1: TOT COMMISSIONS | P1: COMMISSIONS LIAB | Q1: DISCOUNTS | R1: TOT LIAB | S1: TOT LIAB DISC | T1: PROFIT PR | U1: PROFIT EQ | V1: TOT PROFIT | W1: PROFIT LIAB
A2: 0 | B2: =DATA!B2*0.8 -> 80000 | C2: =DATA!B2*0.2*(1-DATA!E4) -> 15000 | D2: =B2+C2 -> 95000 | E2: =1 -> 1 | F2: =1 -> 1 | G2: =D2-20 -> 94980 | H2: =MAX(D2,$B$2+$C$2) -> 95000 | M2: =B2 -> 80000 | N2: =C2 -> 15000 | Q2: =RATES!G3 -> 1
A3: 1 | B3: =B2*EXP(RATES!O4)*(1-DATA!$B$6) -> 80989.354 | C3: =C2*EXP(RATES!O4)*(1-DATA!$B$6) -> 15185.504 | D3: =B3+C3 -> 96174.857 | E3: =E2*(1-'LIFE TABLE MALE'!D63/1000) -> 0.99353213 | F3: =F2*(1-0.15) -> 0.85 | G3: =D3-20 -> 96154.857 | H3: =MAX(D3,$B$2+$C$2) -> 96174.857 | I3: =G3*DATA!$B$7*F2*E3 -> 14329.941 | J3: =H3*'LIFE TABLE MALE'!D63/1000*F2*E2 -> 622.04647 | K3: =0 -> 0 | L3: =DATA!$B$8*((1+DATA!$B$9)^A2)*F3*E3 -> 42.225116 | M3: =B2*EXP(RATES!O4)*(DATA!$B$12) -> 1159.3568 | N3: =C2*EXP(RATES!O4)*(DATA!$B$12) -> 217.3794 | O3: =M3+N3 -> 1376.7362 | P3: =O3*E3*F3 -> 1162.6569 | Q3: =RATES!G4 -> 0.9660529 | R3: =P3+L3+K3+J3+I3 -> 16156.87 | S3: =R3*Q3 -> 15608.391 | T3: =C2*EXP(RATES!O4)*(DATA!$B$6-DATA!$B$12) -> 124.2168 | U3: =B2*EXP(RATES!O4)*(DATA!$B$6-DATA!$B$12) -> 662.4896 | V3: =T3+U3 -> 786.7064 | W3: =V3*E3*F3 -> 664.37537
A4: 2 | B4: =B3*EXP(RATES!O5)*(1-DATA!$B$6) -> 81233.889 | C4: =C3*EXP(RATES!O5)*(1-DATA!$B$6) -> 15231.354 | D4: =B4+C4 -> 96465.244 | E4: =E3*(1-'LIFE TABLE MALE'!D64/1000) -> 0.98647779 | F4: =F3*(1-0.15) -> 0.7225 | G4: =D4-20 -> 96445.244 | H4: =MAX(D4,$B$2+$C$2) -> 96465.244 | I4: =G4*DATA!$B$7*F3*E4 -> 12130.489 | J4: =H4*'LIFE TABLE MALE'!D64/1000*F3*E3 -> 578.42354 | K4: =0 -> 0 | L4: =DATA!$B$8*((1+DATA!$B$9)^A3)*F4*E4 -> 36.34924 | M4: =B3*EXP(RATES!O5)*(DATA!$B$12) -> 1162.8573 | N4: =C3*EXP(RATES!O5)*(DATA!$B$12) -> 218.03575 | O4: =M4+N4 -> 1380.8931 | P4: =O4*E4*F4 -> 984.20419 | Q4: =RATES!G5 -> 0.94195564 | R4: =P4+L4+K4+J4+I4 -> 13729.466 | S4: =R4*Q4 -> 12932.548 | T4: =C3*EXP(RATES!O5)*(DATA!$B$6-DATA!$B$12) -> 124.59185 | U4: =B3*EXP(RATES!O5)*(DATA!$B$6-DATA!$B$12) -> 664.48989 | V4: =T4+U4 -> 789.08175 | W4: =V4*E4*F4 -> 562.4024
A5: 3 | B5: =B4*EXP(RATES!O6)*(1-DATA!$B$6) -> 81258.803 | C5: =C4*EXP(RATES!O6)*(1-DATA!$B$6) -> 15236.026 | D5: =B5+C5 -> 96494.828 | E5: =E4*(1-'LIFE TABLE MALE'!D65/1000) -> 0.97876837 | F5: =F4*(1-0.15) -> 0.614125 | G5: =D5-20 -> 96474.828 | H5: =MAX(D5,$B$2+$C$2) -> 96494.828 | I5: =G5*DATA!$B$7*F4*E5 -> 10233.473 | J5: =H5*'LIFE TABLE MALE'!D65/1000*F4*E4 -> 537.48178 | K5: =0 -> 0 | L5: =DATA!$B$8*((1+DATA!$B$9)^A4)*F5*E5 -> 31.2685 | M5: =B4*EXP(RATES!O6)*(DATA!$B$12) -> 1163.2139 | N5: =C4*EXP(RATES!O6)*(DATA!$B$12) -> 218.10262 | O5: =M5+N5 -> 1381.3166 | P5: =O5*E5*F5 -> 830.29022 | Q5: =RATES!G6 -> 0.92095017 | R5: =P5+L5+K5+J5+I5 -> 11632.514 | S5: =R5*Q5 -> 10712.965 | T5: =C4*EXP(RATES!O6)*(DATA!$B$6-DATA!$B$12) -> 124.63007 | U5: =B4*EXP(RATES!O6)*(DATA!$B$6-DATA!$B$12) -> 664.69368 | V5: =T5+U5 -> 789.32375 | W5: =V5*E5*F5 -> 474.45156
A6: 4 | B6: =B5*EXP(RATES!O7)*(1-DATA!$B$6) -> 81219.667 | C6: =C5*EXP(RATES!O7)*(1-DATA!$B$6) -> 15228.688 | D6: =B6+C6 -> 96448.354 | E6: =E5*(1-'LIFE TABLE MALE'!D66/1000) -> 0.97028747 | F6: =F5*(1-0.15) -> 0.52200625 | G6: =D6-20 -> 96428.354 | H6: =MAX(D6,$B$2+$C$2) -> 96448.354 | I6: =G6*DATA!$B$7*F5*E6 -> 8618.9272 | J6: =H6*'LIFE TABLE MALE'!D66/1000*F5*E5 -> 502.33516 | K6: =0 -> 0 | L6: =DATA!$B$8*((1+DATA!$B$9)^A5)*F6*E6 -> 26.874887 | M6: =B5*EXP(RATES!O7)*(DATA!$B$12) -> 1162.6537 | N6: =C5*EXP(RATES!O7)*(DATA!$B$12) -> 217.99757 | O6: =M6+N6 -> 1380.6513 | P6: =O6*E6*F6 -> 699.29453 | Q6: =RATES!G7 -> 0.90112326 | R6: =P6+L6+K6+J6+I6 -> 9847.4318 | S6: =R6*Q6 -> 8873.7499 | T6: =C5*EXP(RATES!O7)*(DATA!$B$6-DATA!$B$12) -> 124.57004 | U6: =B5*EXP(RATES!O7)*(DATA!$B$6-DATA!$B$12) -> 664.37355 | V6: =T6+U6 -> 788.94359 | W6: =V6*E6*F6 -> 399.59687
A7: 5 | B7: =B6*EXP(RATES!O8)*(1-DATA!$B$6) -> 81178.572 | C7: =C6*EXP(RATES!O8)*(1-DATA!$B$6) -> 15220.982 | D7: =B7+C7 -> 96399.555 | E7: =E6*(1-'LIFE TABLE MALE'!D67/1000) -> 0.96092158 | F7: =F6*(1-0.15) -> 0.44370531 | G7: =D7-20 -> 96379.555 | H7: =MAX(D7,$B$2+$C$2) -> 96399.555 | I7: =G7*DATA!$B$7*F6*E7 -> 7251.6999 | J7: =H7*'LIFE TABLE MALE'!D67/1000*F6*E6 -> 471.30274 | K7: =0 -> 0 | L7: =DATA!$B$8*((1+DATA!$B$9)^A6)*F7*E7 -> 23.075614 | M7: =B6*EXP(RATES!O8)*(DATA!$B$12) -> 1162.0655 | N7: =C6*EXP(RATES!O8)*(DATA!$B$12) -> 217.88727 | O7: =M7+N7 -> 1379.9527 | P7: =O7*E7*F7 -> 588.36494 | Q7: =RATES!G8 -> 0.88174469 | R7: =P7+L7+K7+J7+I7 -> 8334.4432 | S7: =R7*Q7 -> 7348.851 | T7: =C6*EXP(RATES!O8)*(DATA!$B$6-DATA!$B$12) -> 124.50701 | U7: =B6*EXP(RATES!O8)*(DATA!$B$6-DATA!$B$12) -> 664.0374 | V7: =T7+U7 -> 788.54441 | W7: =V7*E7*F7 -> 336.20853
A8: 6 | B8: =B7*EXP(RATES!O9)*(1-DATA!$B$6) -> 81192.731 | C8: =C7*EXP(RATES!O9)*(1-DATA!$B$6) -> 15223.637 | D8: =B8+C8 -> 96416.369 | E8: =E7*(1-'LIFE TABLE MALE'!D68/1000) -> 0.95054817 | F8: =F7*(1-0.15) -> 0.37714952 | G8: =D8-20 -> 96396.369 | H8: =MAX(D8,$B$2+$C$2) -> 96416.369 | I8: =G8*DATA!$B$7*F7*E8 -> 6098.4672 | J8: =H8*'LIFE TABLE MALE'!D68/1000*F7*E7 -> 443.77911 | K8: =0 -> 0 | L8: =DATA!$B$8*((1+DATA!$B$9)^A7)*F8*E8 -> 19.790581 | M8: =B7*EXP(RATES!O9)*(DATA!$B$12) -> 1162.2681 | N8: =C7*EXP(RATES!O9)*(DATA!$B$12) -> 217.92528 | O8: =M8+N8 -> 1380.1934 | P8: =O8*E8*F8 -> 494.79766 | Q8: =RATES!G9 -> 0.86219592 | R8: =P8+L8+K8+J8+I8 -> 7056.8345 | S8: =R8*Q8 -> 6084.3739 | T8: =C7*EXP(RATES!O9)*(DATA!$B$6-DATA!$B$12) -> 124.52873 | U8: =B7*EXP(RATES!O9)*(DATA!$B$6-DATA!$B$12) -> 664.15322 | V8: =T8+U8 -> 788.68195 | W8: =V8*E8*F8 -> 282.74152
A9: 7 | B9: =B8*EXP(RATES!O10)*(1-DATA!$B$6) -> 81254.382 | C9: =C8*EXP(RATES!O10)*(1-DATA!$B$6) -> 15235.197 | D9: =B9+C9 -> 96489.579 | E9: =E8*(1-'LIFE TABLE MALE'!D69/1000) -> 0.93939989 | F9: =F8*(1-0.15) -> 0.32057709 | G9: =D9-20 -> 96469.579 | H9: =MAX(D9,$B$2+$C$2) -> 96489.579 | I9: =G9*DATA!$B$7*F8*E9 -> 5126.792 | J9: =H9*'LIFE TABLE MALE'!D69/1000*F8*E8 -> 405.69689 | K9: =0 -> 0 | L9: =DATA!$B$8*((1+DATA!$B$9)^A8)*F9*E9 -> 16.957195 | M9: =B8*EXP(RATES!O10)*(DATA!$B$12) -> 1163.1507 | N9: =C8*EXP(RATES!O10)*(DATA!$B$12) -> 218.09075 | O9: =M9+N9 -> 1381.2414 | P9: =O9*E9*F9 -> 415.96096 | Q9: =RATES!G10 -> 0.84258782 | R9: =P9+L9+K9+J9+I9 -> 5965.4071 | S9: =R9*Q9 -> 5026.3794 | T9: =C8*EXP(RATES!O10)*(DATA!$B$6-DATA!$B$12) -> 124.62329 | U9: =B8*EXP(RATES!O10)*(DATA!$B$6-DATA!$B$12) -> 664.65752 | V9: =T9+U9 -> 789.28081 | W9: =V9*E9*F9 -> 237.69198
A10: 8 | B10: =B9*EXP(RATES!O11)*(1-DATA!$B$6) -> 81365.273 | C10: =C9*EXP(RATES!O11)*(1-DATA!$B$6) -> 15255.989 | D10: =B10+C10 -> 96621.262 | E10: =E9*(1-'LIFE TABLE MALE'!D70/1000) -> 0.92737751 | F10: =F9*(1-0.15) -> 0.27249053 | G10: =D10-20 -> 96601.262 | H10: =MAX(D10,$B$2+$C$2) -> 96621.262 | I10: =G10*DATA!$B$7*F9*E10 -> 4307.8751 | J10: =H10*'LIFE TABLE MALE'!D70/1000*F9*E9 -> 372.38807 | K10: =0 -> 0 | L10: =DATA!$B$8*((1+DATA!$B$9)^A9)*F10*E10 -> 14.513734 | M10: =B9*EXP(RATES!O11)*(DATA!$B$12) -> 1164.7381 | N10: =C9*EXP(RATES!O11)*(DATA!$B$12) -> 218.38839 | O10: =M10+N10 -> 1383.1265 | P10: =O10*E10*F10 -> 349.51825 | Q10: =RATES!G11 -> 0.82292781 | R10: =P10+L10+K10+J10+I10 -> 5044.2951 | S10: =R10*Q10 -> 4151.0907 | T10: =C9*EXP(RATES!O11)*(DATA!$B$6-DATA!$B$12) -> 124.79336 | U10: =B9*EXP(RATES!O11)*(DATA!$B$6-DATA!$B$12) -> 665.56461 | V10: =T10+U10 -> 790.35797 | W10: =V10*E10*F10 -> 199.72471
A11: 9 | B11: =B10*EXP(RATES!O12)*(1-DATA!$B$6) -> 81523.24 | C11: =C10*EXP(RATES!O12)*(1-DATA!$B$6) -> 15285.608 | D11: =B11+C11 -> 96808.848 | E11: =E10*(1-'LIFE TABLE MALE'!D71/1000) -> 0.91441742 | F11: =F10*(1-0.15) -> 0.23161695 | G11: =D11-20 -> 96788.848 | H11: =MAX(D11,$B$2+$C$2) -> 96808.848 | I11: =G11*DATA!$B$7*F10*E11 -> 3617.5328 | J11: =H11*'LIFE TABLE MALE'!D71/1000*F10*E10 -> 341.88065 | K11: =0 -> 0 | L11: =DATA!$B$8*((1+DATA!$B$9)^A10)*F11*E11 -> 12.407555 | M11: =B10*EXP(RATES!O12)*(DATA!$B$12) -> 1166.9993 | N11: =C10*EXP(RATES!O12)*(DATA!$B$12) -> 218.81238 | O11: =M11+N11 -> 1385.8117 | P11: =O11*E11*F11 -> 293.5074 | Q11: =RATES!G12 -> 0.8032639 | R11: =P11+L11+K11+J11+I11 -> 4265.3284 | S11: =R11*Q11 -> 3426.1843 | T11: =C10*EXP(RATES!O12)*(DATA!$B$6-DATA!$B$12) -> 125.03564 | U11: =B10*EXP(RATES!O12)*(DATA!$B$6-DATA!$B$12) -> 666.85677 | V11: =T11+U11 -> 791.89242 | W11: =V11*E11*F11 -> 167.71851
A12: 10 | B12: =B11*EXP(RATES!O13)*(1-DATA!$B$6) -> 81742.12 | C12: =C11*EXP(RATES!O13)*(1-DATA!$B$6) -> 15326.647 | D12: =B12+C12 -> 97068.767 | E12: =E11*(1-'LIFE TABLE MALE'!D72/1000) -> 0.9000976 | F12: =F11*(1-0.15) -> 0.1968744 | G12: =D12-20 -> 97048.767 | H12: =MAX(D12,$B$2+$C$2) -> 97068.767 | I12: =G12*DATA!$B$7*F11*E12 -> 3034.8779 | J12: =H12*'LIFE TABLE MALE'!D72/1000*F11*E11 -> 321.9493 | K12: =0 -> 0 | L12: =DATA!$B$8*((1+DATA!$B$9)^A11)*F12*E12 -> 10.588889 | M12: =B11*EXP(RATES!O13)*(DATA!$B$12) -> 1170.1326 | N12: =C11*EXP(RATES!O13)*(DATA!$B$12) -> 219.39986 | O12: =M12+N12 -> 1389.5325 | P12: =O12*E12*F12 -> 246.23374 | Q12: =RATES!G13 -> 0.78348852 | R12: =P12+L12+K12+J12+I12 -> 3613.6498 | S12: =R12*Q12 -> 2831.2531 | T12: =C11*EXP(RATES!O13)*(DATA!$B$6-DATA!$B$12) -> 125.37135 | U12: =B11*EXP(RATES!O13)*(DATA!$B$6-DATA!$B$12) -> 668.6472 | V12: =T12+U12 -> 794.01855 | W12: =V12*E12*F12 -> 140.70499
A13: 11 | B13: =B12*EXP(RATES!O14)*(1-DATA!$B$6) -> 82068.024 | C13: =C12*EXP(RATES!O14)*(1-DATA!$B$6) -> 15387.754 | D13: =B13+C13 -> 97455.778 | E13: =E12*(1-'LIFE TABLE MALE'!D73/1000) -> 0.88436967 | F13: =F12*(1-0.15) -> 0.16734324 | G13: =D13-20 -> 97435.778 | H13: =MAX(D13,$B$2+$C$2) -> 97455.778 | I13: =G13*DATA!$B$7*F12*E13 -> 2544.6779 | J13: =H13*'LIFE TABLE MALE'!D73/1000*F12*E12 -> 301.76464 | K13: =0 -> 0 | L13: =DATA!$B$8*((1+DATA!$B$9)^A12)*F13*E13 -> 9.0201497 | M13: =B12*EXP(RATES!O14)*(DATA!$B$12) -> 1174.7979 | N13: =C12*EXP(RATES!O14)*(DATA!$B$12) -> 220.2746 | O13: =M13+N13 -> 1395.0725 | P13: =O13*E13*F13 -> 206.46137 | Q13: =RATES!G14 -> 0.76320888 | R13: =P13+L13+K13+J13+I13 -> 3061.924 | S13: =R13*Q13 -> 2336.8876 | T13: =C12*EXP(RATES!O14)*(DATA!$B$6-DATA!$B$12) -> 125.8712 | U13: =B12*EXP(RATES!O14)*(DATA!$B$6-DATA!$B$12) -> 671.31308 | V13: =T13+U13 -> 797.18428 | W13: =V13*E13*F13 -> 117.97792
A14: 12 | B14: =B13*EXP(RATES!O15)*(1-DATA!$B$6) -> 82258.657 | C14: =C13*EXP(RATES!O15)*(1-DATA!$B$6) -> 15423.498 | D14: =B14+C14 -> 97682.155 | E14: =E13*(1-'LIFE TABLE MALE'!D74/1000) -> 0.86691444 | F14: =F13*(1-0.15) -> 0.14224176 | G14: =D14-20 -> 97662.155 | H14: =MAX(D14,$B$2+$C$2) -> 97682.155 | I14: =G14*DATA!$B$7*F13*E14 -> 2125.2106 | J14: =H14*'LIFE TABLE MALE'!D74/1000*F13*E13 -> 285.331 | K14: =0 -> 0 | L14: =DATA!$B$8*((1+DATA!$B$9)^A13)*F14*E14 -> 7.6661134 | M14: =B13*EXP(RATES!O15)*(DATA!$B$12) -> 1177.5268 | N14: =C13*EXP(RATES!O15)*(DATA!$B$12) -> 220.78627 | O14: =M14+N14 -> 1398.3131 | P14: =O14*E14*F14 -> 172.42799 | Q14: =RATES!G15 -> 0.74468847 | R14: =P14+L14+K14+J14+I14 -> 2590.6357 | S14: =R14*Q14 -> 1929.2166 | T14: =C13*EXP(RATES!O15)*(DATA!$B$6-DATA!$B$12) -> 126.16358 | U14: =B13*EXP(RATES!O15)*(DATA!$B$6-DATA!$B$12) -> 672.87245 | V14: =T14+U14 -> 799.03603 | W14: =V14*E14*F14 -> 98.530278
... A51: 49 | B51: =B50*EXP(RATES!O52)*(1-DATA!$B$6) -> 102111.48 | C51: =C50*EXP(RATES!O52)*(1-DATA!$B$6) -> 19145.902 | D51: =B51+C51 -> 121257.38 | E51: =E50*(1-'LIFE TABLE MALE'!D111/1000) -> 2.6221013e-06 | F51: =F50*(1-0.15) -> 0.00034795843 | G51: =D51-20 -> 121237.38 | H51: =MAX(D51,$B$2+$C$2) -> 121257.38 | I51: =G51*DATA!$B$7*F50*E51 -> 1.9520264e-05 | J51: =H51*'LIFE TABLE MALE'!D111/1000*F50*E50 -> 0.00032049145 | K51: =0 -> 0 | L51: =DATA!$B$8*((1+DATA!$B$9)^A50)*F51*E51 -> 1.1801985e-07 | M51: =B50*EXP(RATES!O52)*(DATA!$B$12) -> 1461.7185 | N51: =C50*EXP(RATES!O52)*(DATA!$B$12) -> 274.07221 | O51: =M51+N51 -> 1735.7907 | P51: =O51*E51*F51 -> 1.5837046e-06 | Q51: =RATES!G52 -> 0.26340215 | R51: =P51+L51+K51+J51+I51 -> 0.00034171344 | S51: =R51*Q51 -> 9.0008054e-05 | T51: =C50*EXP(RATES!O52)*(DATA!$B$6-DATA!$B$12) -> 156.61269 | U51: =B50*EXP(RATES!O52)*(DATA!$B$6-DATA!$B$12) -> 835.2677 | V51: =T51+U51 -> 991.88039 | W51: =V51*E51*F51 -> 9.0497406e-07
A52: 50 | B52: =B51*EXP(RATES!O53)*(1-DATA!$B$6) -> 103172 | C52: =C51*EXP(RATES!O53)*(1-DATA!$B$6) -> 19344.75 | D52: =B52+C52 -> 122516.75 | E52: =E51*(1-'LIFE TABLE MALE'!D112/1000) -> 6.7948871e-07 | F52: =F51*(1-0.15) -> 0.00029576466 | G52: =D52-20 -> 122496.75 | H52: =MAX(D52,$B$2+$C$2) -> 122516.75 | I52: =G52*DATA!$B$7*F51*E52 -> 4.3443562e-06 | J52: =H52*'LIFE TABLE MALE'!D112/1000*F51*E51 -> 8.2815004e-05 | K52: =E52*D52*F52 -> 2.4622038e-05 | L52: =DATA!$B$8*((1+DATA!$B$9)^A51)*F52*E52 -> 2.6515935e-08 | M52: =B51*EXP(RATES!O53)*(DATA!$B$12) -> 1476.8998 | N52: =C51*EXP(RATES!O53)*(DATA!$B$12) -> 276.91871 | O52: =M52+N52 -> 1753.8185 | P52: =O52*E52*F52 -> 3.5246271e-07 | Q52: =RATES!G53 -> 0.25495931 | R52: =P52+L52+K52+J52+I52 -> 0.00011216038 | S52: =R52*Q52 -> 2.8596332e-05 | T52: =C51*EXP(RATES!O53)*(DATA!$B$6-DATA!$B$12) -> 158.23926 | U52: =B51*EXP(RATES!O53)*(DATA!$B$6-DATA!$B$12) -> 843.94273 | V52: =T52+U52 -> 1002.182 | W52: =V52*E52*F52 -> 2.0140726e-07
P56: LIABILITIES | Q56: =SUM(S3:S52) -> 89780.518 | T56: BEL COMPONENTS
P57: BOF | Q57: =$B$2+$C$2-Q56 -> 5219.4825 | T57: DEATH | U57: =SUMPRODUCT(J3:J52,Q3:Q52) -> 6107.1947
T58: LAPSE | U58: =SUMPRODUCT(I3:I52,Q3:Q52) -> 77164.947
P59: DURATION | Q59: =SUMPRODUCT(S3:S52,A3:A52)/SUM(S3:S52) -> 5.6130992 | T59: EXPENSES | U59: =SUMPRODUCT(L3:L52,Q3:Q52) -> 247.61987
T60: COMMISSIONS | U60: =SUMPRODUCT(P3:P52,Q3:Q52) -> 6260.7561

Sheet IR UP 
B1: EQUITY | C1: PROPERTY | D1: ASSET | E1: SURVIVAL PROB | F1: non LAPSE PROB | G1: C lapse | H1: C death | I1: LIAB LAPSE | J1: LIAB DEATH | K1: LIAB SURVIVE | L1: EXPENSES | M1: EQ COMMISSIONS | N1: PR COMMISSIONS | O1: TOT COMMISSIONS | P1: COMMISSIONS LIAB | Q1: DISCOUNTS | R1: TOT LIAB | S1: TOT LIAB DISC | T1: PROFIT PR | U1: PROFIT EQ | V1: TOT PROFIT | W1: PROFIT LIAB
A2: 0 | B2: =DATA!B2*0.8 -> 80000 | C2: =DATA!B2*0.2 -> 20000 | D2: =B2+C2 -> 100000 | E2: =1 -> 1 | F2: =1 -> 1 | G2: =D2-20 -> 99980 | H2: =MAX(D2,DATA!$B$3) -> 100000 | M2: =B2 -> 80000 | N2: =C2 -> 20000 | Q2: =RATES!G3 -> 1
A3: 1 | B3: =B2*EXP(RATES!P4)*(1-DATA!$B$6) -> 82914.058 | C3: =C2*EXP(RATES!P4)*(1-DATA!$B$6) -> 20728.514 | D3: =B3+C3 -> 103642.57 | E3: =E2*(1-'LIFE TABLE MALE'!D63/1000) -> 0.99353213 | F3: =F2*(1-0.15) -> 0.85 | G3: =D3-20 -> 103622.57 | H3: =MAX(D3,DATA!$B$3) -> 103642.57 | I3: =G3*DATA!$B$7*F2*E3 -> 15442.853 | J3: =H3*'LIFE TABLE MALE'!D63/1000*F2*E2 -> 670.34668 | K3: =0 -> 0 | L3: =DATA!$B$8*((1+DATA!$B$9)^A2)*F3*E3 -> 42.225116 | M3: =B2*EXP(RATES!P4)*(DATA!$B$12) -> 1186.9088 | N3: =C2*EXP(RATES!P4)*(DATA!$B$12) -> 296.7272 | O3: =M3+N3 -> 1483.636 | P3: =O3*E3*F3 -> 1252.934 | Q3: =RATES!H4 -> 0.94362768 | R3: =P3+L3+K3+J3+I3 -> 17408.359 | S3: =R3*Q3 -> 16427.009 | T3: =C2*EXP(RATES!P4)*(DATA!$B$6-DATA!$B$12) -> 169.5584 | U3: =B2*EXP(RATES!P4)*(DATA!$B$6-DATA!$B$12) -> 678.2336 | V3: =T3+U3 -> 847.792 | W3: =V3*E3*F3 -> 715.9623
A4: 2 | B4: =B3*EXP(RATES!P5)*(1-DATA!$B$6) -> 84619.188 | C4: =C3*EXP(RATES!P5)*(1-DATA!$B$6) -> 21154.797 | D4: =B4+C4 -> 105773.98 | E4: =E3*(1-'LIFE TABLE MALE'!D64/1000) -> 0.98647779 | F4: =F3*(1-0.15) -> 0.7225 | G4: =D4-20 -> 105753.98 | H4: =MAX(D4,DATA!$B$3) -> 105773.98 | I4: =G4*DATA!$B$7*F3*E4 -> 13301.305 | J4: =H4*'LIFE TABLE MALE'!D64/1000*F3*E3 -> 634.24048 | K4: =0 -> 0 | L4: =DATA!$B$8*((1+DATA!$B$9)^A3)*F4*E4 -> 36.34924 | M4: =B3*EXP(RATES!P5)*(DATA!$B$12) -> 1211.3176 | N4: =C3*EXP(RATES!P5)*(DATA!$B$12) -> 302.8294 | O4: =M4+N4 -> 1514.147 | P4: =O4*E4*F4 -> 1079.1783 | Q4: =RATES!H5 -> 0.9042715 | R4: =P4+L4+K4+J4+I4 -> 15051.073 | S4: =R4*Q4 -> 13610.256 | T4: =C3*EXP(RATES!P5)*(DATA!$B$6-DATA!$B$12) -> 173.04537 | U4: =B3*EXP(RATES!P5)*(DATA!$B$6-DATA!$B$12) -> 692.18149 | V4: =T4+U4 -> 865.22687 | W4: =V4*E4*F4 -> 616.67332
A5: 3 | B5: =B4*EXP(RATES!P6)*(1-DATA!$B$6) -> 85556.521 | C5: =C4*EXP(RATES!P6)*(1-DATA!$B$6) -> 21389.13 | D5: =B5+C5 -> 106945.65 | E5: =E4*(1-'LIFE TABLE MALE'!D65/1000) -> 0.97876837 | F5: =F4*(1-0.15) -> 0.614125 | G5: =D5-20 -> 106925.65 | H5: =MAX(D5,DATA!$B$3) -> 106945.65 | I5: =G5*DATA!$B$7*F4*E5 -> 11342.034 | J5: =H5*'LIFE TABLE MALE'!D65/1000*F4*E4 -> 595.69346 | K5: =0 -> 0 | L5: =DATA!$B$8*((1+DATA!$B$9)^A4)*F5*E5 -> 31.2685 | M5: =B4*EXP(RATES!P6)*(DATA!$B$12) -> 1224.7355 | N5: =C4*EXP(RATES!P6)*(DATA!$B$12) -> 306.18387 | O5: =M5+N5 -> 1530.9193 | P5: =O5*E5*F5 -> 920.21438 | Q5: =RATES!H6 -> 0.87468854 | R5: =P5+L5+K5+J5+I5 -> 12889.21 | S5: =R5*Q5 -> 11274.044 | T5: =C4*EXP(RATES!P6)*(DATA!$B$6-DATA!$B$12) -> 174.96221 | U5: =B4*EXP(RATES!P6)*(DATA!$B$6-DATA!$B$12) -> 699.84884 | V5: =T5+U5 -> 874.81105 | W5: =V5*E5*F5 -> 525.83679
A6: 4 | B6: =B5*EXP(RATES!P7)*(1-DATA!$B$6) -> 86258.038 | C6: =C5*EXP(RATES!P7)*(1-DATA!$B$6) -> 21564.51 | D6: =B6+C6 -> 107822.55 | E6: =E5*(1-'LIFE TABLE MALE'!D66/1000) -> 0.97028747 | F6: =F5*(1-0.15) -> 0.52200625 | G6: =D6-20 -> 107802.55 | H6: =MAX(D6,DATA!$B$3) -> 107822.55 | I6: =G6*DATA!$B$7*F5*E6 -> 9635.5716 | J6: =H6*'LIFE TABLE MALE'!D66/1000*F5*E5 -> 561.57575 | K6: =0 -> 0 | L6: =DATA!$B$8*((1+DATA!$B$9)^A5)*F6*E6 -> 26.874887 | M6: =B5*EXP(RATES!P7)*(DATA!$B$12) -> 1234.7776 | N6: =C5*EXP(RATES!P7)*(DATA!$B$12) -> 308.69441 | O6: =M6+N6 -> 1543.4721 | P6: =O6*E6*F6 -> 781.76261 | Q6: =RATES!H7 -> 0.84848824 | R6: =P6+L6+K6+J6+I6 -> 11005.785 | S6: =R6*Q6 -> 9338.2791 | T6: =C5*EXP(RATES!P7)*(DATA!$B$6-DATA!$B$12) -> 176.39681 | U6: =B5*EXP(RATES!P7)*(DATA!$B$6-DATA!$B$12) -> 705.58723 | V6: =T6+U6 -> 881.98403 | W6: =V6*E6*F6 -> 446.72149
A7: 5 | B7: =B6*EXP(RATES!P8)*(1-DATA!$B$6) -> 86881.562 | C7: =C6*EXP(RATES!P8)*(1-DATA!$B$6) -> 21720.39 | D7: =B7+C7 -> 108601.95 | E7: =E6*(1-'LIFE TABLE MALE'!D67/1000) -> 0.96092158 | F7: =F6*(1-0.15) -> 0.44370531 | G7: =D7-20 -> 108581.95 | H7: =MAX(D7,DATA!$B$3) -> 108601.95 | I7: =G7*DATA!$B$7*F6*E7 -> 8169.8212 | J7: =H7*'LIFE TABLE MALE'!D67/1000*F6*E6 -> 530.96093 | K7: =0 -> 0 | L7: =DATA!$B$8*((1+DATA!$B$9)^A6)*F7*E7 -> 23.075614 | M7: =B6*EXP(RATES!P8)*(DATA!$B$12) -> 1243.7033 | N7: =C6*EXP(RATES!P8)*(DATA!$B$12) -> 310.92583 | O7: =M7+N7 -> 1554.6292 | P7: =O7*E7*F7 -> 662.84103 | Q7: =RATES!H8 -> 0.82386612 | R7: =P7+L7+K7+J7+I7 -> 9386.6988 | S7: =R7*Q7 -> 7733.3831 | T7: =C6*EXP(RATES!P8)*(DATA!$B$6-DATA!$B$12) -> 177.67191 | U7: =B6*EXP(RATES!P8)*(DATA!$B$6-DATA!$B$12) -> 710.68762 | V7: =T7+U7 -> 888.35953 | W7: =V7*E7*F7 -> 378.76631
A8: 6 | B8: =B7*EXP(RATES!P9)*(1-DATA!$B$6) -> 87575.484 | C8: =C7*EXP(RATES!P9)*(1-DATA!$B$6) -> 21893.871 | D8: =B8+C8 -> 109469.36 | E8: =E7*(1-'LIFE TABLE MALE'!D68/1000) -> 0.95054817 | F8: =F7*(1-0.15) -> 0.37714952 | G8: =D8-20 -> 109449.36 | H8: =MAX(D8,DATA!$B$3) -> 109469.36 | I8: =G8*DATA!$B$7*F7*E8 -> 6924.2577 | J8: =H8*'LIFE TABLE MALE'!D68/1000*F7*E7 -> 503.85856 | K8: =0 -> 0 | L8: =DATA!$B$8*((1+DATA!$B$9)^A7)*F8*E8 -> 19.790581 | M8: =B7*EXP(RATES!P9)*(DATA!$B$12) -> 1253.6368 | N8: =C7*EXP(RATES!P9)*(DATA!$B$12) -> 313.4092 | O8: =M8+N8 -> 1567.046 | P8: =O8*E8*F8 -> 561.78408 | Q8: =RATES!H9 -> 0.79935661 | R8: =P8+L8+K8+J8+I8 -> 8009.6909 | S8: =R8*Q8 -> 6402.5994 | T8: =C7*EXP(RATES!P9)*(DATA!$B$6-DATA!$B$12) -> 179.09097 | U8: =B7*EXP(RATES!P9)*(DATA!$B$6-DATA!$B$12) -> 716.36388 | V8: =T8+U8 -> 895.45485 | W8: =V8*E8*F8 -> 321.01947
A9: 7 | B9: =B8*EXP(RATES!P10)*(1-DATA!$B$6) -> 88236.731 | C9: =C8*EXP(RATES!P10)*(1-DATA!$B$6) -> 22059.183 | D9: =B9+C9 -> 110295.91 | E9: =E8*(1-'LIFE TABLE MALE'!D69/1000) -> 0.93939989 | F9: =F8*(1-0.15) -> 0.32057709 | G9: =D9-20 -> 110275.91 | H9: =MAX(D9,DATA!$B$3) -> 110295.91 | I9: =G9*DATA!$B$7*F8*E9 -> 5860.5177 | J9: =H9*'LIFE TABLE MALE'!D69/1000*F8*E8 -> 463.74655 | K9: =0 -> 0 | L9: =DATA!$B$8*((1+DATA!$B$9)^A8)*F9*E9 -> 16.957195 | M9: =B8*EXP(RATES!P10)*(DATA!$B$12) -> 1263.1025 | N9: =C8*EXP(RATES!P10)*(DATA!$B$12) -> 315.77562 | O9: =M9+N9 -> 1578.8781 | P9: =O9*E9*F9 -> 475.47927 | Q9: =RATES!H10 -> 0.77591216 | R9: =P9+L9+K9+J9+I9 -> 6816.7008 | S9: =R9*Q9 -> 5289.161 | T9: =C8*EXP(RATES!P10)*(DATA!$B$6-DATA!$B$12) -> 180.44321 | U9: =B8*EXP(RATES!P10)*(DATA!$B$6-DATA!$B$12) -> 721.77285 | V9: =T9+U9 -> 902.21606 | W9: =V9*E9*F9 -> 271.70244
